2023-02-11 19:13:24.883 WARNING (SyncWorker_3) [homeassistant.loader] We found a custom integration hello_miai which has not been tested by Home Assistant. This component might cause stability problems, be sure to disable it if you experience issues with Home Assistant
2023-02-11 19:13:24.890 WARNING (SyncWorker_3) [homeassistant.loader] We found a custom integration xiaomi_miot_raw which has not been tested by Home Assistant. This component might cause stability problems, be sure to disable it if you experience issues with Home Assistant
2023-02-11 19:13:24.893 WARNING (SyncWorker_3) [homeassistant.loader] We found a custom integration hacs which has not been tested by Home Assistant. This component might cause stability problems, be sure to disable it if you experience issues with Home Assistant
2023-02-11 19:13:24.896 WARNING (SyncWorker_3) [homeassistant.loader] We found a custom integration heweather_hourlyforecast which has not been tested by Home Assistant. This component might cause stability problems, be sure to disable it if you experience issues with Home Assistant
2023-02-11 19:13:24.899 WARNING (SyncWorker_3) [homeassistant.loader] We found a custom integration edge_tts which has not been tested by Home Assistant. This component might cause stability problems, be sure to disable it if you experience issues with Home Assistant
2023-02-11 19:13:24.902 WARNING (SyncWorker_3) [homeassistant.loader] We found a custom integration xiaomi_miot which has not been tested by Home Assistant. This component might cause stability problems, be sure to disable it if you experience issues with Home Assistant
2023-02-11 19:13:24.905 WARNING (SyncWorker_3) [homeassistant.loader] We found a custom integration huawei_mesh_router which has not been tested by Home Assistant. This component might cause stability problems, be sure to disable it if you experience issues with Home Assistant
2023-02-11 19:13:24.908 WARNING (SyncWorker_3) [homeassistant.loader] We found a custom integration lifesuggestion which has not been tested by Home Assistant. This component might cause stability problems, be sure to disable it if you experience issues with Home Assistant
2023-02-11 19:13:24.911 WARNING (SyncWorker_3) [homeassistant.loader] We found a custom integration xiaomi_gateway3 which has not been tested by Home Assistant. This component might cause stability problems, be sure to disable it if you experience issues with Home Assistant
2023-02-11 19:13:24.914 WARNING (SyncWorker_3) [homeassistant.loader] We found a custom integration heweather which has not been tested by Home Assistant. This component might cause stability problems, be sure to disable it if you experience issues with Home Assistant
2023-02-11 19:13:24.917 WARNING (SyncWorker_3) [homeassistant.loader] We found a custom integration heweather_forecast which has not been tested by Home Assistant. This component might cause stability problems, be sure to disable it if you experience issues with Home Assistant
2023-02-11 19:13:24.920 WARNING (SyncWorker_3) [homeassistant.loader] We found a custom integration nodered which has not been tested by Home Assistant. This component might cause stability problems, be sure to disable it if you experience issues with Home Assistant
2023-02-11 19:13:24.923 WARNING (SyncWorker_3) [homeassistant.loader] We found a custom integration hasslife which has not been tested by Home Assistant. This component might cause stability problems, be sure to disable it if you experience issues with Home Assistant
2023-02-11 19:13:33.227 WARNING (MainThread) [homeassistant.components.weather] custom_components.heweather_forecast.weather::LocalWeather is overriding deprecated methods on an instance of WeatherEntity, this is not valid and will be unsupported from Home Assistant 2023.1. Please report it to the custom integration author.
2023-02-11 19:13:36.433 WARNING (MainThread) [homeassistant.components.switch] Platform broadlink not ready yet: None; Retrying in background in 30 seconds
2023-02-11 19:13:42.663 WARNING (MainThread) [homeassistant.config_entries] Config entry 'Wi-Fi智能插座' for broadlink integration not ready yet: [Errno -4000] Network timeout: No response received within 5s; Retrying in background
2023-02-11 19:13:47.074 WARNING (MainThread) [homeassistant.config_entries] Config entry 'SP-MINI' for broadlink integration not ready yet: [Errno -4000] Network timeout: No response received within 10s; Retrying in background
2023-02-11 19:14:11.800 ERROR (MainThread) [homeassistant.components.homekit.util] media_player.xiao_ai_yin_xiang_5219 does not support any media_player features
2023-02-11 19:14:11.854 ERROR (MainThread) [homeassistant.components.homekit.util] media_player.plex_plex_for_kodi_kodi1 does not support any media_player features
2023-02-11 19:14:11.877 ERROR (MainThread) [homeassistant.components.homekit.util] media_player.plex_plex_web_microsoft_edge_windows does not support any media_player features
2023-02-11 19:14:11.919 ERROR (MainThread) [homeassistant.components.homekit.util] media_player.plex_plex_for_windows_x13 does not support any media_player features
2023-02-11 19:15:27.568 WARNING (MainThread) [homeassistant.components.manual.alarm_control_panel] Invalid code given for armed_away
2023-02-11 19:15:29.870 WARNING (MainThread) [homeassistant.components.manual.alarm_control_panel] Invalid code given for armed_away
2023-02-11 19:29:57.712 WARNING (MainThread) [homeassistant.helpers.entity] Update of binary_sensor.door_window_sensor_158d0001a64708 is taking over 10 seconds
2023-02-11 19:29:57.721 ERROR (SyncWorker_2) [xiaomi_gateway] Cannot connect to gateway 286c07f0c4e5
2023-02-11 19:29:57.737 ERROR (SyncWorker_2) [xiaomi_gateway] No data in response from hub None
2023-02-11 19:33:45.420 ERROR (MainThread) [homeassistant.components.broadlink.updater] Error fetching s1 (MP1-1K4S at 192.168.1.33) data: [Errno -4000] Network timeout: No response received within 5s
2023-02-11 19:36:52.937 WARNING (MainThread) [custom_components.huawei_mesh_router.update_coordinator (Huawei Router)] Can not update repeater state Can not perform GET request at api/ntwk/repeaterinfo cause of TimeoutError(); code: -3, category: request_error
2023-02-11 19:36:58.935 WARNING (MainThread) [custom_components.huawei_mesh_router.update_coordinator (Huawei Router)] Can not update wlan filter info: Can not perform GET request at api/ntwk/wlanfilterenhance cause of TimeoutError(); code: -3, category: request_error
2023-02-11 19:39:36.767 ERROR (MainThread) [plexwebsocket] Websocket connection failed, retrying in 15s: Cannot connect to host 192.168.1.8:32400 ssl:default [Connect call failed ('192.168.1.8', 32400)]
2023-02-11 19:39:51.788 ERROR (MainThread) [plexwebsocket] Websocket connection failed, retrying in 30s: Cannot connect to host 192.168.1.8:32400 ssl:default [Connect call failed ('192.168.1.8', 32400)]
2023-02-11 19:40:21.804 ERROR (MainThread) [plexwebsocket] Websocket connection failed, retrying in 60s: Cannot connect to host 192.168.1.8:32400 ssl:default [Connect call failed ('192.168.1.8', 32400)]
2023-02-11 19:41:21.821 ERROR (MainThread) [plexwebsocket] Websocket connection failed, retrying in 120s: Cannot connect to host 192.168.1.8:32400 ssl:default [Connect call failed ('192.168.1.8', 32400)]
2023-02-11 19:43:24.870 ERROR (MainThread) [plexwebsocket] Websocket connection failed, retrying in 240s: Cannot connect to host 192.168.1.8:32400 ssl:default [Connect call failed ('192.168.1.8', 32400)]
2023-02-11 19:43:45.590 ERROR (MainThread) [homeassistant.components.plex.server] Could not connect to Plex server: MY-NAS (HTTPConnectionPool(host='192.168.1.8', port=32400): Max retries exceeded with url: /clients (Caused by NewConnectionError('<urllib3.connection.HTTPConnection object at 0x7f9e5f5780>: Failed to establish a new connection: [Errno 113] Host is unreachable')))
2023-02-11 19:44:17.694 ERROR (MainThread) [aiohttp.server] Error handling request
Traceback (most recent call last):
  File "/usr/local/lib/python3.10/site-packages/aiohttp/connector.py", line 986, in _wrap_create_connection
    return await self._loop.create_connection(*args, **kwargs)  # type: ignore[return-value]  # noqa
  File "/usr/local/lib/python3.10/asyncio/base_events.py", line 1064, in create_connection
    raise exceptions[0]
  File "/usr/local/lib/python3.10/asyncio/base_events.py", line 1049, in create_connection
    sock = await self._connect_sock(
  File "/usr/local/lib/python3.10/asyncio/base_events.py", line 960, in _connect_sock
    await self.sock_connect(sock, address)
  File "/usr/local/lib/python3.10/asyncio/selector_events.py", line 500, in sock_connect
    return await fut
  File "/usr/local/lib/python3.10/asyncio/selector_events.py", line 535, in _sock_connect_cb
    raise OSError(err, f'Connect call failed {address}')
ConnectionRefusedError: [Errno 111] Connect call failed ('192.168.1.8', 32400)

The above exception was the direct cause of the following exception:

Traceback (most recent call last):
  File "/usr/local/lib/python3.10/site-packages/aiohttp/web_protocol.py", line 435, in _handle_request
    resp = await request_handler(request)
  File "/usr/local/lib/python3.10/site-packages/aiohttp/web_app.py", line 504, in _handle
    resp = await handler(request)
  File "/usr/local/lib/python3.10/site-packages/aiohttp/web_middlewares.py", line 117, in impl
    return await handler(request)
  File "/usr/src/homeassistant/homeassistant/components/http/security_filter.py", line 60, in security_filter_middleware
    return await handler(request)
  File "/usr/src/homeassistant/homeassistant/components/http/forwarded.py", line 100, in forwarded_middleware
    return await handler(request)
  File "/usr/src/homeassistant/homeassistant/components/http/request_context.py", line 28, in request_context_middleware
    return await handler(request)
  File "/usr/src/homeassistant/homeassistant/components/http/ban.py", line 80, in ban_middleware
    return await handler(request)
  File "/usr/src/homeassistant/homeassistant/components/http/auth.py", line 236, in auth_middleware
    return await handler(request)
  File "/usr/src/homeassistant/homeassistant/components/http/view.py", line 145, in handle
    result = await result
  File "/usr/src/homeassistant/homeassistant/components/media_player/__init__.py", line 1170, in get
    data, content_type = await player.async_get_media_image()
  File "/usr/src/homeassistant/homeassistant/components/media_player/__init__.py", line 586, in async_get_media_image
    return await self._async_fetch_image_from_cache(url)
  File "/usr/src/homeassistant/homeassistant/components/media_player/__init__.py", line 1088, in _async_fetch_image_from_cache
    (content, content_type) = await self._async_fetch_image(url)
  File "/usr/src/homeassistant/homeassistant/components/media_player/__init__.py", line 1099, in _async_fetch_image
    return await async_fetch_image(_LOGGER, self.hass, url)
  File "/usr/src/homeassistant/homeassistant/components/media_player/__init__.py", line 1265, in async_fetch_image
    response = await websession.get(url)
  File "/usr/local/lib/python3.10/site-packages/aiohttp/client.py", line 535, in _request
    conn = await self._connector.connect(
  File "/usr/local/lib/python3.10/site-packages/aiohttp/connector.py", line 542, in connect
    proto = await self._create_connection(req, traces, timeout)
  File "/usr/local/lib/python3.10/site-packages/aiohttp/connector.py", line 907, in _create_connection
    _, proto = await self._create_direct_connection(req, traces, timeout)
  File "/usr/local/lib/python3.10/site-packages/aiohttp/connector.py", line 1206, in _create_direct_connection
    raise last_exc
  File "/usr/local/lib/python3.10/site-packages/aiohttp/connector.py", line 1175, in _create_direct_connection
    transp, proto = await self._wrap_create_connection(
  File "/usr/local/lib/python3.10/site-packages/aiohttp/connector.py", line 992, in _wrap_create_connection
    raise client_error(req.connection_key, exc) from exc
aiohttp.client_exceptions.ClientConnectorError: Cannot connect to host 192.168.1.8:32400 ssl:default [Connect call failed ('192.168.1.8', 32400)]
2023-02-11 19:45:09.619 WARNING (MainThread) [homeassistant.components.media_player] Error retrieving proxied image from http://192.168.1.8:32400/library/metadata/22288/thumb/1676062356?X-Plex-Token=hF7cqjXxsXEvbzHivzY9
2023-02-11 19:56:27.775 WARNING (MainThread) [homeassistant.helpers.entity] Update of binary_sensor.door_window_sensor_158d0001a64708 is taking over 10 seconds
2023-02-11 19:56:27.784 ERROR (SyncWorker_5) [xiaomi_gateway] Cannot connect to gateway 286c07f0c4e5
2023-02-11 19:56:27.790 ERROR (SyncWorker_5) [xiaomi_gateway] No data in response from hub None
2023-02-11 20:28:57.771 WARNING (MainThread) [homeassistant.helpers.entity] Update of switch.plug_158d00015d1bf5 is taking over 10 seconds
2023-02-11 20:28:57.779 ERROR (SyncWorker_8) [xiaomi_gateway] Cannot connect to gateway 286c07f0c4e5
2023-02-11 20:28:57.786 ERROR (SyncWorker_8) [xiaomi_gateway] No data in response from hub None
2023-02-11 20:28:57.859 WARNING (MainThread) [homeassistant.helpers.entity] Update of binary_sensor.door_window_sensor_158d0001a64708 is taking over 10 seconds
2023-02-11 20:28:57.867 ERROR (SyncWorker_5) [xiaomi_gateway] Cannot connect to gateway 286c07f0c4e5
2023-02-11 20:28:57.870 ERROR (SyncWorker_5) [xiaomi_gateway] No data in response from hub None
2023-02-11 20:29:07.880 WARNING (MainThread) [homeassistant.helpers.entity] Update of binary_sensor.door_window_sensor_158d000128fa46 is taking over 10 seconds
2023-02-11 20:29:07.889 ERROR (SyncWorker_1) [xiaomi_gateway] Cannot connect to gateway 286c07f0c4e5
2023-02-11 20:29:07.893 ERROR (SyncWorker_1) [xiaomi_gateway] No data in response from hub None
2023-02-11 20:29:27.771 WARNING (MainThread) [homeassistant.helpers.entity] Update of switch.plug_158d00015d1bf5 is taking over 10 seconds
2023-02-11 20:29:27.781 ERROR (SyncWorker_6) [xiaomi_gateway] Cannot connect to gateway 286c07f0c4e5
2023-02-11 20:29:27.785 ERROR (SyncWorker_6) [xiaomi_gateway] No data in response from hub None
2023-02-11 20:29:27.862 WARNING (MainThread) [homeassistant.helpers.entity] Update of binary_sensor.door_window_sensor_158d0001a64708 is taking over 10 seconds
2023-02-11 20:29:27.871 ERROR (SyncWorker_0) [xiaomi_gateway] Cannot connect to gateway 286c07f0c4e5
2023-02-11 20:29:27.874 ERROR (SyncWorker_0) [xiaomi_gateway] No data in response from hub None
2023-02-11 20:29:58.008 WARNING (MainThread) [homeassistant.helpers.entity] Update of binary_sensor.door_window_sensor_158d000128fa46 is taking over 10 seconds
2023-02-11 20:29:58.015 ERROR (SyncWorker_0) [xiaomi_gateway] Cannot connect to gateway 286c07f0c4e5
2023-02-11 20:29:58.018 ERROR (SyncWorker_0) [xiaomi_gateway] No data in response from hub None
2023-02-11 20:30:58.172 WARNING (MainThread) [homeassistant.helpers.entity] Update of binary_sensor.door_window_sensor_158d000128fa46 is taking over 10 seconds
2023-02-11 20:30:58.181 ERROR (SyncWorker_7) [xiaomi_gateway] Cannot connect to gateway 286c07f0c4e5
2023-02-11 20:30:58.187 ERROR (SyncWorker_7) [xiaomi_gateway] No data in response from hub None
2023-02-11 20:31:27.776 WARNING (MainThread) [homeassistant.helpers.entity] Update of switch.plug_158d00015d1bf5 is taking over 10 seconds
2023-02-11 20:31:27.784 ERROR (SyncWorker_7) [xiaomi_gateway] Cannot connect to gateway 286c07f0c4e5
2023-02-11 20:31:27.791 ERROR (SyncWorker_7) [xiaomi_gateway] No data in response from hub None
2023-02-11 20:31:48.150 ERROR (MainThread) [homeassistant.components.broadlink.updater] Error fetching s2 (MP1-1K4S at 192.168.1.34) data: [Errno -4000] Network timeout: No response received within 5s
2023-02-11 20:31:57.777 WARNING (MainThread) [homeassistant.helpers.entity] Update of switch.plug_158d00015d1bf5 is taking over 10 seconds
2023-02-11 20:31:57.784 ERROR (SyncWorker_1) [xiaomi_gateway] Cannot connect to gateway 286c07f0c4e5
2023-02-11 20:31:57.787 ERROR (SyncWorker_1) [xiaomi_gateway] No data in response from hub None
2023-02-11 20:31:57.869 WARNING (MainThread) [homeassistant.helpers.entity] Update of binary_sensor.door_window_sensor_158d0001a64708 is taking over 10 seconds
2023-02-11 20:31:57.878 ERROR (SyncWorker_3) [xiaomi_gateway] Cannot connect to gateway 286c07f0c4e5
2023-02-11 20:31:57.885 ERROR (SyncWorker_3) [xiaomi_gateway] No data in response from hub None
2023-02-11 20:32:07.896 WARNING (MainThread) [homeassistant.helpers.entity] Update of binary_sensor.door_window_sensor_158d000128fa46 is taking over 10 seconds
2023-02-11 20:32:07.911 ERROR (SyncWorker_6) [xiaomi_gateway] Cannot connect to gateway 286c07f0c4e5
2023-02-11 20:32:07.914 ERROR (SyncWorker_6) [xiaomi_gateway] No data in response from hub None
2023-02-11 20:32:27.871 WARNING (MainThread) [homeassistant.helpers.entity] Update of binary_sensor.door_window_sensor_158d0001a64708 is taking over 10 seconds
2023-02-11 20:32:27.879 ERROR (SyncWorker_5) [xiaomi_gateway] Cannot connect to gateway 286c07f0c4e5
2023-02-11 20:32:27.882 ERROR (SyncWorker_5) [xiaomi_gateway] No data in response from hub None
2023-02-11 20:32:37.888 WARNING (MainThread) [homeassistant.helpers.entity] Update of binary_sensor.door_window_sensor_158d000128fa46 is taking over 10 seconds
2023-02-11 20:32:37.897 ERROR (SyncWorker_1) [xiaomi_gateway] Cannot connect to gateway 286c07f0c4e5
2023-02-11 20:32:37.904 ERROR (SyncWorker_1) [xiaomi_gateway] No data in response from hub None
2023-02-11 20:32:57.870 WARNING (MainThread) [homeassistant.helpers.entity] Update of binary_sensor.door_window_sensor_158d0001a64708 is taking over 10 seconds
2023-02-11 20:32:57.879 ERROR (SyncWorker_6) [xiaomi_gateway] Cannot connect to gateway 286c07f0c4e5
2023-02-11 20:32:57.882 ERROR (SyncWorker_6) [xiaomi_gateway] No data in response from hub None
2023-02-11 20:33:57.783 WARNING (MainThread) [homeassistant.helpers.entity] Update of switch.plug_158d00015d1bf5 is taking over 10 seconds
2023-02-11 20:33:57.791 ERROR (SyncWorker_9) [xiaomi_gateway] Cannot connect to gateway 286c07f0c4e5
2023-02-11 20:33:57.794 ERROR (SyncWorker_9) [xiaomi_gateway] No data in response from hub None
2023-02-11 20:34:27.784 WARNING (MainThread) [homeassistant.helpers.entity] Update of switch.plug_158d00015d1bf5 is taking over 10 seconds
2023-02-11 20:34:27.791 ERROR (SyncWorker_6) [xiaomi_gateway] Cannot connect to gateway 286c07f0c4e5
2023-02-11 20:34:27.794 ERROR (SyncWorker_6) [xiaomi_gateway] No data in response from hub None
2023-02-11 20:34:57.786 WARNING (MainThread) [homeassistant.helpers.entity] Update of switch.plug_158d00015d1bf5 is taking over 10 seconds
2023-02-11 20:34:57.794 ERROR (SyncWorker_2) [xiaomi_gateway] Cannot connect to gateway 286c07f0c4e5
2023-02-11 20:34:57.800 ERROR (SyncWorker_2) [xiaomi_gateway] No data in response from hub None
2023-02-11 20:34:57.878 WARNING (MainThread) [homeassistant.helpers.entity] Update of binary_sensor.door_window_sensor_158d0001a64708 is taking over 10 seconds
2023-02-11 20:34:57.885 ERROR (SyncWorker_4) [xiaomi_gateway] Cannot connect to gateway 286c07f0c4e5
2023-02-11 20:34:57.890 ERROR (SyncWorker_4) [xiaomi_gateway] No data in response from hub None
2023-02-11 20:35:54.149 ERROR (MainThread) [homeassistant.components.broadlink.updater] Error fetching s2 (MP1-1K4S at 192.168.1.34) data: [Errno -4000] Network timeout: No response received within 5s
2023-02-11 20:35:57.932 WARNING (MainThread) [homeassistant.helpers.entity] Update of binary_sensor.door_window_sensor_158d000128fa46 is taking over 10 seconds
2023-02-11 20:35:57.941 ERROR (SyncWorker_9) [xiaomi_gateway] Cannot connect to gateway 286c07f0c4e5
2023-02-11 20:35:57.944 ERROR (SyncWorker_9) [xiaomi_gateway] No data in response from hub None
2023-02-11 20:36:57.793 WARNING (MainThread) [homeassistant.helpers.entity] Update of switch.plug_158d00015d1bf5 is taking over 10 seconds
2023-02-11 20:36:57.799 ERROR (SyncWorker_9) [xiaomi_gateway] Cannot connect to gateway 286c07f0c4e5
2023-02-11 20:36:57.804 ERROR (SyncWorker_9) [xiaomi_gateway] No data in response from hub None
2023-02-11 20:36:57.882 WARNING (MainThread) [homeassistant.helpers.entity] Update of binary_sensor.door_window_sensor_158d0001a64708 is taking over 10 seconds
2023-02-11 20:36:57.891 ERROR (SyncWorker_6) [xiaomi_gateway] Cannot connect to gateway 286c07f0c4e5
2023-02-11 20:36:57.897 ERROR (SyncWorker_6) [xiaomi_gateway] No data in response from hub None
2023-02-11 20:37:27.893 WARNING (MainThread) [homeassistant.helpers.entity] Update of binary_sensor.door_window_sensor_158d0001a64708 is taking over 10 seconds
2023-02-11 20:37:27.901 ERROR (SyncWorker_2) [xiaomi_gateway] Cannot connect to gateway 286c07f0c4e5
2023-02-11 20:37:27.907 ERROR (SyncWorker_2) [xiaomi_gateway] No data in response from hub None
2023-02-11 20:37:37.913 WARNING (MainThread) [homeassistant.helpers.entity] Update of binary_sensor.door_window_sensor_158d000128fa46 is taking over 10 seconds
2023-02-11 20:37:37.921 ERROR (SyncWorker_7) [xiaomi_gateway] Cannot connect to gateway 286c07f0c4e5
2023-02-11 20:37:37.927 ERROR (SyncWorker_7) [xiaomi_gateway] No data in response from hub None
2023-02-11 20:37:57.923 WARNING (MainThread) [homeassistant.helpers.entity] Update of binary_sensor.door_window_sensor_158d000128fa46 is taking over 10 seconds
2023-02-11 20:37:57.931 ERROR (SyncWorker_7) [xiaomi_gateway] Cannot connect to gateway 286c07f0c4e5
2023-02-11 20:37:57.938 ERROR (SyncWorker_7) [xiaomi_gateway] No data in response from hub None
2023-02-11 20:38:27.887 WARNING (MainThread) [homeassistant.helpers.entity] Update of binary_sensor.door_window_sensor_158d0001a64708 is taking over 10 seconds
2023-02-11 20:38:27.896 ERROR (SyncWorker_6) [xiaomi_gateway] Cannot connect to gateway 286c07f0c4e5
2023-02-11 20:38:27.901 ERROR (SyncWorker_6) [xiaomi_gateway] No data in response from hub None
2023-02-11 20:40:27.904 WARNING (MainThread) [homeassistant.helpers.entity] Update of binary_sensor.door_window_sensor_158d000128fa46 is taking over 10 seconds
2023-02-11 20:40:27.914 ERROR (SyncWorker_1) [xiaomi_gateway] Cannot connect to gateway 286c07f0c4e5
2023-02-11 20:40:27.920 ERROR (SyncWorker_1) [xiaomi_gateway] No data in response from hub None
2023-02-11 20:40:57.893 WARNING (MainThread) [homeassistant.helpers.entity] Update of binary_sensor.door_window_sensor_158d0001a64708 is taking over 10 seconds
2023-02-11 20:40:57.902 ERROR (SyncWorker_5) [xiaomi_gateway] Cannot connect to gateway 286c07f0c4e5
2023-02-11 20:40:57.908 ERROR (SyncWorker_5) [xiaomi_gateway] No data in response from hub None
2023-02-11 20:46:27.929 WARNING (MainThread) [homeassistant.helpers.entity] Update of binary_sensor.door_window_sensor_158d000128fa46 is taking over 10 seconds
2023-02-11 20:46:27.937 ERROR (SyncWorker_3) [xiaomi_gateway] Cannot connect to gateway 286c07f0c4e5
2023-02-11 20:46:27.944 ERROR (SyncWorker_3) [xiaomi_gateway] No data in response from hub None
2023-02-11 20:53:48.552 ERROR (Thread-193 (_connect)) [plexapi] http://192.168.1.6:32500: HTTPConnectionPool(host='192.168.1.6', port=32500): Max retries exceeded with url: /resources (Caused by NewConnectionError('<urllib3.connection.HTTPConnection object at 0x7f7d129270>: Failed to establish a new connection: [Errno 113] Host is unreachable'))
2023-02-11 20:53:48.555 ERROR (Thread-192 (_connect)) [plexapi] http://192.168.1.6:32500: HTTPConnectionPool(host='192.168.1.6', port=32500): Max retries exceeded with url: /resources (Caused by NewConnectionError('<urllib3.connection.HTTPConnection object at 0x7f7d12b250>: Failed to establish a new connection: [Errno 113] Host is unreachable'))
2023-02-11 20:53:48.591 ERROR (SyncWorker_3) [homeassistant.components.plex.server] Resource connection failed to plex.tv: p2301
2023-02-11 20:54:08.524 ERROR (Thread-195 (_connect)) [plexapi] http://192.168.1.6:32500: HTTPConnectionPool(host='192.168.1.6', port=32500): Max retries exceeded with url: /resources (Caused by NewConnectionError('<urllib3.connection.HTTPConnection object at 0x7f90f40a60>: Failed to establish a new connection: [Errno 113] Host is unreachable'))
2023-02-11 20:54:08.526 ERROR (Thread-194 (_connect)) [plexapi] http://192.168.1.6:32500: HTTPConnectionPool(host='192.168.1.6', port=32500): Max retries exceeded with url: /resources (Caused by NewConnectionError('<urllib3.connection.HTTPConnection object at 0x7f7d12a530>: Failed to establish a new connection: [Errno 113] Host is unreachable'))
2023-02-11 20:54:08.559 ERROR (SyncWorker_1) [homeassistant.components.plex.server] Resource connection failed to plex.tv: p2301
2023-02-11 21:02:57.977 WARNING (MainThread) [homeassistant.helpers.entity] Update of binary_sensor.door_window_sensor_158d000128fa46 is taking over 10 seconds
2023-02-11 21:02:57.984 ERROR (SyncWorker_2) [xiaomi_gateway] Cannot connect to gateway 286c07f0c4e5
2023-02-11 21:02:57.987 ERROR (SyncWorker_2) [xiaomi_gateway] No data in response from hub None
2023-02-11 21:03:48.465 ERROR (Thread-197 (_connect)) [plexapi] http://192.168.1.6:32500: HTTPConnectionPool(host='192.168.1.6', port=32500): Max retries exceeded with url: /resources (Caused by ConnectTimeoutError(<urllib3.connection.HTTPConnection object at 0x7fa1ba0c40>, 'Connection to 192.168.1.6 timed out. (connect timeout=3)'))
2023-02-11 21:03:48.467 ERROR (Thread-196 (_connect)) [plexapi] http://192.168.1.6:32500: HTTPConnectionPool(host='192.168.1.6', port=32500): Max retries exceeded with url: /resources (Caused by ConnectTimeoutError(<urllib3.connection.HTTPConnection object at 0x7f7f245f90>, 'Connection to 192.168.1.6 timed out. (connect timeout=3)'))
2023-02-11 21:03:48.522 ERROR (SyncWorker_3) [homeassistant.components.plex.server] Resource connection failed to plex.tv: p2301
2023-02-11 21:04:27.871 WARNING (MainThread) [homeassistant.helpers.entity] Update of switch.plug_158d00015d1bf5 is taking over 10 seconds
2023-02-11 21:04:27.877 ERROR (SyncWorker_8) [xiaomi_gateway] Cannot connect to gateway 286c07f0c4e5
2023-02-11 21:04:27.886 ERROR (SyncWorker_8) [xiaomi_gateway] No data in response from hub None
2023-02-11 21:14:57.910 WARNING (MainThread) [homeassistant.helpers.entity] Update of switch.plug_158d00015d1bf5 is taking over 10 seconds
2023-02-11 21:14:57.918 ERROR (SyncWorker_3) [xiaomi_gateway] Cannot connect to gateway 286c07f0c4e5
2023-02-11 21:14:57.925 ERROR (SyncWorker_3) [xiaomi_gateway] No data in response from hub None
2023-02-11 21:17:57.919 WARNING (MainThread) [homeassistant.helpers.entity] Update of switch.plug_158d00015d1bf5 is taking over 10 seconds
2023-02-11 21:17:57.927 ERROR (SyncWorker_2) [xiaomi_gateway] Cannot connect to gateway 286c07f0c4e5
2023-02-11 21:17:57.933 ERROR (SyncWorker_2) [xiaomi_gateway] No data in response from hub None
2023-02-11 21:18:27.983 WARNING (MainThread) [homeassistant.helpers.entity] Update of binary_sensor.door_window_sensor_158d0001a64708 is taking over 10 seconds
2023-02-11 21:18:27.990 ERROR (SyncWorker_3) [xiaomi_gateway] Cannot connect to gateway 286c07f0c4e5
2023-02-11 21:18:27.993 ERROR (SyncWorker_3) [xiaomi_gateway] No data in response from hub None
2023-02-11 21:19:28.035 WARNING (MainThread) [homeassistant.helpers.entity] Update of binary_sensor.door_window_sensor_158d000128fa46 is taking over 10 seconds
2023-02-11 21:19:28.044 ERROR (SyncWorker_0) [xiaomi_gateway] Cannot connect to gateway 286c07f0c4e5
2023-02-11 21:19:28.050 ERROR (SyncWorker_0) [xiaomi_gateway] No data in response from hub None
2023-02-11 21:21:27.990 WARNING (MainThread) [homeassistant.helpers.entity] Update of binary_sensor.door_window_sensor_158d0001a64708 is taking over 10 seconds
2023-02-11 21:21:27.998 ERROR (SyncWorker_4) [xiaomi_gateway] Cannot connect to gateway 286c07f0c4e5
2023-02-11 21:21:28.005 ERROR (SyncWorker_4) [xiaomi_gateway] No data in response from hub None
2023-02-11 21:22:57.933 WARNING (MainThread) [homeassistant.helpers.entity] Update of switch.plug_158d00015d1bf5 is taking over 10 seconds
2023-02-11 21:22:57.944 ERROR (SyncWorker_1) [xiaomi_gateway] Cannot connect to gateway 286c07f0c4e5
2023-02-11 21:22:57.951 ERROR (SyncWorker_1) [xiaomi_gateway] No data in response from hub None
2023-02-11 21:22:57.993 WARNING (MainThread) [homeassistant.helpers.entity] Update of binary_sensor.door_window_sensor_158d0001a64708 is taking over 10 seconds
2023-02-11 21:22:58.001 ERROR (SyncWorker_3) [xiaomi_gateway] Cannot connect to gateway 286c07f0c4e5
2023-02-11 21:22:58.007 ERROR (SyncWorker_3) [xiaomi_gateway] No data in response from hub None
2023-02-11 21:27:27.949 WARNING (MainThread) [homeassistant.helpers.entity] Update of switch.plug_158d00015d1bf5 is taking over 10 seconds
2023-02-11 21:27:27.958 ERROR (SyncWorker_0) [xiaomi_gateway] Cannot connect to gateway 286c07f0c4e5
2023-02-11 21:27:27.962 ERROR (SyncWorker_0) [xiaomi_gateway] No data in response from hub None
2023-02-11 21:27:28.004 WARNING (MainThread) [homeassistant.helpers.entity] Update of binary_sensor.door_window_sensor_158d0001a64708 is taking over 10 seconds
2023-02-11 21:27:28.014 ERROR (SyncWorker_1) [xiaomi_gateway] Cannot connect to gateway 286c07f0c4e5
2023-02-11 21:27:28.018 ERROR (SyncWorker_1) [xiaomi_gateway] No data in response from hub None
2023-02-11 21:27:38.025 WARNING (MainThread) [homeassistant.helpers.entity] Update of binary_sensor.door_window_sensor_158d000128fa46 is taking over 10 seconds
2023-02-11 21:27:38.032 ERROR (SyncWorker_5) [xiaomi_gateway] Cannot connect to gateway 286c07f0c4e5
2023-02-11 21:27:38.038 ERROR (SyncWorker_5) [xiaomi_gateway] No data in response from hub None
2023-02-11 21:27:50.428 ERROR (MainThread) [homeassistant.components.broadlink.updater] Error fetching s1 (MP1-1K4S at 192.168.1.33) data: [Errno -4000] Network timeout: No response received within 5s
2023-02-11 21:27:58.011 WARNING (MainThread) [homeassistant.helpers.entity] Update of binary_sensor.door_window_sensor_158d0001a64708 is taking over 10 seconds
2023-02-11 21:27:58.020 ERROR (SyncWorker_5) [xiaomi_gateway] Cannot connect to gateway 286c07f0c4e5
2023-02-11 21:27:58.023 ERROR (SyncWorker_5) [xiaomi_gateway] No data in response from hub None
2023-02-11 21:29:10.149 ERROR (MainThread) [homeassistant.components.broadlink.updater] Error fetching s2 (MP1-1K4S at 192.168.1.34) data: [Errno -4000] Network timeout: No response received within 5s
2023-02-11 21:30:28.676 WARNING (MainThread) [homeassistant.helpers.entity] Update of binary_sensor.door_window_sensor_158d000128fa46 is taking over 10 seconds
2023-02-11 21:30:28.684 ERROR (SyncWorker_2) [xiaomi_gateway] Cannot connect to gateway 286c07f0c4e5
2023-02-11 21:30:28.690 ERROR (SyncWorker_2) [xiaomi_gateway] No data in response from hub None
2023-02-11 21:30:57.959 WARNING (MainThread) [homeassistant.helpers.entity] Update of switch.plug_158d00015d1bf5 is taking over 10 seconds
2023-02-11 21:30:57.967 ERROR (SyncWorker_3) [xiaomi_gateway] Cannot connect to gateway 286c07f0c4e5
2023-02-11 21:30:57.973 ERROR (SyncWorker_3) [xiaomi_gateway] No data in response from hub None
2023-02-11 21:38:57.984 WARNING (MainThread) [homeassistant.helpers.entity] Update of switch.plug_158d00015d1bf5 is taking over 10 seconds
2023-02-11 21:38:57.990 ERROR (SyncWorker_8) [xiaomi_gateway] Cannot connect to gateway 286c07f0c4e5
2023-02-11 21:38:57.997 ERROR (SyncWorker_8) [xiaomi_gateway] No data in response from hub None
2023-02-11 21:46:28.004 WARNING (MainThread) [homeassistant.helpers.entity] Update of switch.plug_158d00015d1bf5 is taking over 10 seconds
2023-02-11 21:46:28.014 ERROR (SyncWorker_5) [xiaomi_gateway] Cannot connect to gateway 286c07f0c4e5
2023-02-11 21:46:28.020 ERROR (SyncWorker_5) [xiaomi_gateway] No data in response from hub None
2023-02-11 21:47:28.007 WARNING (MainThread) [homeassistant.helpers.entity] Update of switch.plug_158d00015d1bf5 is taking over 10 seconds
2023-02-11 21:47:28.015 ERROR (SyncWorker_5) [xiaomi_gateway] Cannot connect to gateway 286c07f0c4e5
2023-02-11 21:47:28.020 ERROR (SyncWorker_5) [xiaomi_gateway] No data in response from hub None
2023-02-11 21:55:16.148 ERROR (MainThread) [homeassistant.components.broadlink.updater] Error fetching s2 (MP1-1K4S at 192.168.1.34) data: [Errno -4000] Network timeout: No response received within 5s
2023-02-11 21:59:28.079 WARNING (MainThread) [homeassistant.helpers.entity] Update of binary_sensor.door_window_sensor_158d0001a64708 is taking over 10 seconds
2023-02-11 21:59:28.087 ERROR (SyncWorker_9) [xiaomi_gateway] Cannot connect to gateway 286c07f0c4e5
2023-02-11 21:59:28.094 ERROR (SyncWorker_9) [xiaomi_gateway] No data in response from hub None
2023-02-11 22:00:10.362 ERROR (SyncWorker_4) [xiaomi_gateway] Cannot connect to gateway 286c07f0c4e5
2023-02-11 22:00:10.388 ERROR (SyncWorker_4) [xiaomi_gateway] No data in response from hub None
2023-02-11 22:05:28.089 WARNING (MainThread) [homeassistant.helpers.entity] Update of binary_sensor.door_window_sensor_158d0001a64708 is taking over 10 seconds
2023-02-11 22:05:28.098 ERROR (SyncWorker_4) [xiaomi_gateway] Cannot connect to gateway 286c07f0c4e5
2023-02-11 22:05:28.102 ERROR (SyncWorker_4) [xiaomi_gateway] No data in response from hub None
2023-02-11 22:05:55.422 ERROR (MainThread) [homeassistant.components.broadlink.updater] Error fetching s1 (MP1-1K4S at 192.168.1.33) data: [Errno -4000] Network timeout: No response received within 5s
2023-02-11 22:15:58.083 WARNING (MainThread) [homeassistant.helpers.entity] Update of switch.plug_158d00015d1bf5 is taking over 10 seconds
2023-02-11 22:15:58.091 ERROR (SyncWorker_7) [xiaomi_gateway] Cannot connect to gateway 286c07f0c4e5
2023-02-11 22:15:58.098 ERROR (SyncWorker_7) [xiaomi_gateway] No data in response from hub None
2023-02-11 22:15:58.113 WARNING (MainThread) [homeassistant.helpers.entity] Update of binary_sensor.door_window_sensor_158d0001a64708 is taking over 10 seconds
2023-02-11 22:15:58.120 ERROR (SyncWorker_4) [xiaomi_gateway] Cannot connect to gateway 286c07f0c4e5
2023-02-11 22:15:58.126 ERROR (SyncWorker_4) [xiaomi_gateway] No data in response from hub None
2023-02-11 22:18:28.092 WARNING (MainThread) [homeassistant.helpers.entity] Update of switch.plug_158d00015d1bf5 is taking over 10 seconds
2023-02-11 22:18:28.100 ERROR (SyncWorker_7) [xiaomi_gateway] Cannot connect to gateway 286c07f0c4e5
2023-02-11 22:18:28.104 ERROR (SyncWorker_7) [xiaomi_gateway] No data in response from hub None
2023-02-11 22:18:28.121 WARNING (MainThread) [homeassistant.helpers.entity] Update of binary_sensor.door_window_sensor_158d0001a64708 is taking over 10 seconds
2023-02-11 22:18:28.130 ERROR (SyncWorker_4) [xiaomi_gateway] Cannot connect to gateway 286c07f0c4e5
2023-02-11 22:18:28.134 ERROR (SyncWorker_4) [xiaomi_gateway] No data in response from hub None
2023-02-11 22:18:58.093 WARNING (MainThread) [homeassistant.helpers.entity] Update of switch.plug_158d00015d1bf5 is taking over 10 seconds
2023-02-11 22:18:58.102 ERROR (SyncWorker_2) [xiaomi_gateway] Cannot connect to gateway 286c07f0c4e5
2023-02-11 22:18:58.108 ERROR (SyncWorker_2) [xiaomi_gateway] No data in response from hub None
2023-02-11 22:18:58.121 WARNING (MainThread) [homeassistant.helpers.entity] Update of binary_sensor.door_window_sensor_158d0001a64708 is taking over 10 seconds
2023-02-11 22:18:58.130 ERROR (SyncWorker_1) [xiaomi_gateway] Cannot connect to gateway 286c07f0c4e5
2023-02-11 22:18:58.136 ERROR (SyncWorker_1) [xiaomi_gateway] No data in response from hub None
2023-02-11 22:27:28.156 WARNING (MainThread) [homeassistant.helpers.entity] Update of binary_sensor.door_window_sensor_158d000128fa46 is taking over 10 seconds
2023-02-11 22:27:28.163 ERROR (SyncWorker_9) [xiaomi_gateway] Cannot connect to gateway 286c07f0c4e5
2023-02-11 22:27:28.167 ERROR (SyncWorker_9) [xiaomi_gateway] No data in response from hub None
2023-02-11 22:27:58.153 WARNING (MainThread) [homeassistant.helpers.entity] Update of binary_sensor.door_window_sensor_158d000128fa46 is taking over 10 seconds
2023-02-11 22:27:58.160 ERROR (SyncWorker_8) [xiaomi_gateway] Cannot connect to gateway 286c07f0c4e5
2023-02-11 22:27:58.167 ERROR (SyncWorker_8) [xiaomi_gateway] No data in response from hub None
2023-02-11 22:28:58.159 WARNING (MainThread) [homeassistant.helpers.entity] Update of binary_sensor.door_window_sensor_158d000128fa46 is taking over 10 seconds
2023-02-11 22:28:58.167 ERROR (SyncWorker_1) [xiaomi_gateway] Cannot connect to gateway 286c07f0c4e5
2023-02-11 22:28:58.170 ERROR (SyncWorker_1) [xiaomi_gateway] No data in response from hub None
2023-02-11 22:33:58.136 WARNING (MainThread) [homeassistant.helpers.entity] Update of switch.plug_158d00015d1bf5 is taking over 10 seconds
2023-02-11 22:33:58.144 ERROR (SyncWorker_5) [xiaomi_gateway] Cannot connect to gateway 286c07f0c4e5
2023-02-11 22:33:58.151 ERROR (SyncWorker_5) [xiaomi_gateway] No data in response from hub None
2023-02-11 22:34:28.175 WARNING (MainThread) [homeassistant.helpers.entity] Update of binary_sensor.door_window_sensor_158d000128fa46 is taking over 10 seconds
2023-02-11 22:34:28.183 ERROR (SyncWorker_1) [xiaomi_gateway] Cannot connect to gateway 286c07f0c4e5
2023-02-11 22:34:28.190 ERROR (SyncWorker_1) [xiaomi_gateway] No data in response from hub None
2023-02-11 22:34:58.139 WARNING (MainThread) [homeassistant.helpers.entity] Update of switch.plug_158d00015d1bf5 is taking over 10 seconds
2023-02-11 22:34:58.150 ERROR (SyncWorker_9) [xiaomi_gateway] Cannot connect to gateway 286c07f0c4e5
2023-02-11 22:34:58.156 ERROR (SyncWorker_9) [xiaomi_gateway] No data in response from hub None
2023-02-11 22:34:58.161 WARNING (MainThread) [homeassistant.helpers.entity] Update of binary_sensor.door_window_sensor_158d0001a64708 is taking over 10 seconds
2023-02-11 22:34:58.170 ERROR (SyncWorker_2) [xiaomi_gateway] Cannot connect to gateway 286c07f0c4e5
2023-02-11 22:34:58.176 ERROR (SyncWorker_2) [xiaomi_gateway] No data in response from hub None
2023-02-11 22:35:00.421 ERROR (MainThread) [homeassistant.components.broadlink.updater] Error fetching s1 (MP1-1K4S at 192.168.1.33) data: [Errno -4000] Network timeout: No response received within 5s
2023-02-11 22:38:58.152 WARNING (MainThread) [homeassistant.helpers.entity] Update of switch.plug_158d00015d1bf5 is taking over 10 seconds
2023-02-11 22:38:58.160 ERROR (SyncWorker_5) [xiaomi_gateway] Cannot connect to gateway 286c07f0c4e5
2023-02-11 22:38:58.163 ERROR (SyncWorker_5) [xiaomi_gateway] No data in response from hub None
2023-02-11 22:41:28.175 WARNING (MainThread) [homeassistant.helpers.entity] Update of binary_sensor.door_window_sensor_158d0001a64708 is taking over 10 seconds
2023-02-11 22:41:28.183 ERROR (SyncWorker_7) [xiaomi_gateway] Cannot connect to gateway 286c07f0c4e5
2023-02-11 22:41:28.188 ERROR (SyncWorker_7) [xiaomi_gateway] No data in response from hub None
2023-02-11 22:41:38.194 WARNING (MainThread) [homeassistant.helpers.entity] Update of binary_sensor.door_window_sensor_158d000128fa46 is taking over 10 seconds
2023-02-11 22:41:38.200 ERROR (SyncWorker_5) [xiaomi_gateway] Cannot connect to gateway 286c07f0c4e5
2023-02-11 22:41:38.206 ERROR (SyncWorker_5) [xiaomi_gateway] No data in response from hub None
2023-02-11 22:56:28.197 WARNING (MainThread) [homeassistant.helpers.entity] Update of switch.plug_158d00015d1bf5 is taking over 10 seconds
2023-02-11 22:56:28.207 ERROR (SyncWorker_5) [xiaomi_gateway] Cannot connect to gateway 286c07f0c4e5
2023-02-11 22:56:28.213 ERROR (SyncWorker_5) [xiaomi_gateway] No data in response from hub None
2023-02-11 23:03:28.214 WARNING (MainThread) [homeassistant.helpers.entity] Update of switch.plug_158d00015d1bf5 is taking over 10 seconds
2023-02-11 23:03:28.223 ERROR (SyncWorker_3) [xiaomi_gateway] Cannot connect to gateway 286c07f0c4e5
2023-02-11 23:03:28.231 ERROR (SyncWorker_3) [xiaomi_gateway] No data in response from hub None
2023-02-11 23:05:58.220 WARNING (MainThread) [homeassistant.helpers.entity] Update of switch.plug_158d00015d1bf5 is taking over 10 seconds
2023-02-11 23:05:58.230 ERROR (SyncWorker_9) [xiaomi_gateway] Cannot connect to gateway 286c07f0c4e5
2023-02-11 23:05:58.236 ERROR (SyncWorker_9) [xiaomi_gateway] No data in response from hub None
2023-02-11 23:05:58.240 WARNING (MainThread) [homeassistant.helpers.entity] Update of binary_sensor.door_window_sensor_158d0001a64708 is taking over 10 seconds
2023-02-11 23:05:58.248 ERROR (SyncWorker_1) [xiaomi_gateway] Cannot connect to gateway 286c07f0c4e5
2023-02-11 23:05:58.253 ERROR (SyncWorker_1) [xiaomi_gateway] No data in response from hub None
2023-02-11 23:06:58.224 WARNING (MainThread) [homeassistant.helpers.entity] Update of switch.plug_158d00015d1bf5 is taking over 10 seconds
2023-02-11 23:06:58.230 ERROR (SyncWorker_2) [xiaomi_gateway] Cannot connect to gateway 286c07f0c4e5
2023-02-11 23:06:58.233 ERROR (SyncWorker_2) [xiaomi_gateway] No data in response from hub None
2023-02-11 23:10:28.235 WARNING (MainThread) [homeassistant.helpers.entity] Update of switch.plug_158d00015d1bf5 is taking over 10 seconds
2023-02-11 23:10:28.243 ERROR (SyncWorker_5) [xiaomi_gateway] Cannot connect to gateway 286c07f0c4e5
2023-02-11 23:10:28.246 ERROR (SyncWorker_5) [xiaomi_gateway] No data in response from hub None
2023-02-11 23:10:28.251 WARNING (MainThread) [homeassistant.helpers.entity] Update of binary_sensor.door_window_sensor_158d0001a64708 is taking over 10 seconds
2023-02-11 23:10:28.260 ERROR (SyncWorker_4) [xiaomi_gateway] Cannot connect to gateway 286c07f0c4e5
2023-02-11 23:10:28.266 ERROR (SyncWorker_4) [xiaomi_gateway] No data in response from hub None
2023-02-11 23:10:58.283 WARNING (MainThread) [homeassistant.helpers.entity] Update of binary_sensor.door_window_sensor_158d000128fa46 is taking over 10 seconds
2023-02-11 23:10:58.290 ERROR (SyncWorker_1) [xiaomi_gateway] Cannot connect to gateway 286c07f0c4e5
2023-02-11 23:10:58.296 ERROR (SyncWorker_1) [xiaomi_gateway] No data in response from hub None
2023-02-11 23:18:58.257 WARNING (MainThread) [homeassistant.helpers.entity] Update of switch.plug_158d00015d1bf5 is taking over 10 seconds
2023-02-11 23:18:58.271 ERROR (SyncWorker_4) [xiaomi_gateway] Cannot connect to gateway 286c07f0c4e5
2023-02-11 23:18:58.284 WARNING (MainThread) [homeassistant.helpers.entity] Update of binary_sensor.door_window_sensor_158d0001a64708 is taking over 10 seconds
2023-02-11 23:18:58.289 ERROR (SyncWorker_0) [xiaomi_gateway] Cannot connect to gateway 286c07f0c4e5
2023-02-11 23:18:58.295 ERROR (SyncWorker_4) [xiaomi_gateway] No data in response from hub None
2023-02-11 23:18:58.308 ERROR (SyncWorker_0) [xiaomi_gateway] No data in response from hub None
2023-02-11 23:23:58.289 WARNING (MainThread) [homeassistant.helpers.entity] Update of binary_sensor.door_window_sensor_158d0001a64708 is taking over 10 seconds
2023-02-11 23:23:58.297 ERROR (SyncWorker_5) [xiaomi_gateway] Cannot connect to gateway 286c07f0c4e5
2023-02-11 23:23:58.300 ERROR (SyncWorker_5) [xiaomi_gateway] No data in response from hub None
2023-02-11 23:26:28.320 WARNING (MainThread) [homeassistant.helpers.entity] Update of binary_sensor.door_window_sensor_158d000128fa46 is taking over 10 seconds
2023-02-11 23:26:28.327 ERROR (SyncWorker_0) [xiaomi_gateway] Cannot connect to gateway 286c07f0c4e5
2023-02-11 23:26:28.335 ERROR (SyncWorker_0) [xiaomi_gateway] No data in response from hub None
2023-02-11 23:33:28.388 WARNING (MainThread) [homeassistant.helpers.entity] Update of binary_sensor.door_window_sensor_158d000128fa46 is taking over 10 seconds
2023-02-11 23:33:28.396 ERROR (SyncWorker_9) [xiaomi_gateway] Cannot connect to gateway 286c07f0c4e5
2023-02-11 23:33:28.399 ERROR (SyncWorker_9) [xiaomi_gateway] No data in response from hub None
2023-02-11 23:49:58.374 WARNING (MainThread) [homeassistant.helpers.entity] Update of binary_sensor.door_window_sensor_158d000128fa46 is taking over 10 seconds
2023-02-11 23:49:58.383 ERROR (SyncWorker_3) [xiaomi_gateway] Cannot connect to gateway 286c07f0c4e5
2023-02-11 23:49:58.389 ERROR (SyncWorker_3) [xiaomi_gateway] No data in response from hub None
2023-02-11 23:56:28.394 WARNING (MainThread) [homeassistant.helpers.entity] Update of binary_sensor.door_window_sensor_158d000128fa46 is taking over 10 seconds
2023-02-11 23:56:28.403 ERROR (SyncWorker_7) [xiaomi_gateway] Cannot connect to gateway 286c07f0c4e5
2023-02-11 23:56:28.410 ERROR (SyncWorker_7) [xiaomi_gateway] No data in response from hub None
2023-02-12 00:00:00.452 ERROR (MainThread) [homeassistant.components.automation.er_lou_bing_ju_mei_ge_liu_xiao_shi_zhi_xing_kai_guan] 二楼冰柜每隔六小时执行开关: Error executing script. Invalid data for call_service at pos 1: must contain at least one of entity_id, device_id, area_id.
2023-02-12 00:00:00.480 ERROR (MainThread) [homeassistant.components.automation.er_lou_bing_ju_mei_ge_liu_xiao_shi_zhi_xing_kai_guan] Error while executing automation automation.er_lou_bing_ju_mei_ge_liu_xiao_shi_zhi_xing_kai_guan: must contain at least one of entity_id, device_id, area_id.
2023-02-12 02:22:17.381 ERROR (MainThread) [aiohttp.server] Error handling request
Traceback (most recent call last):
  File "/usr/local/lib/python3.10/site-packages/aiohttp/web_protocol.py", line 334, in data_received
    messages, upgraded, tail = self._request_parser.feed_data(data)
  File "aiohttp/_http_parser.pyx", line 551, in aiohttp._http_parser.HttpParser.feed_data
aiohttp.http_exceptions.BadStatusLine: 400, message="Bad status line 'Invalid method encountered'"
2023-02-12 02:30:44.417 ERROR (MainThread) [homeassistant.components.broadlink.updater] Error fetching s3 (MP1-1K4S at 192.168.1.35) data: [Errno -4000] Network timeout: No response received within 5s
2023-02-12 03:45:41.108 WARNING (MainThread) [homeassistant.components.websocket_api.http.connection] [546765874816] Disconnected: Did not receive auth message within 10 seconds
2023-02-12 04:21:47.063 ERROR (MainThread) [homeassistant.components.broadlink.updater] Error fetching 智能遥控 (RM pro at 192.168.1.39) data: [Errno -4000] Network timeout: No response received within 5s
2023-02-12 04:21:59.190 WARNING (MainThread) [homeassistant.helpers.entity] Update of binary_sensor.door_window_sensor_158d0001a64708 is taking over 10 seconds
2023-02-12 04:21:59.198 ERROR (SyncWorker_7) [xiaomi_gateway] Cannot connect to gateway 286c07f0c4e5
2023-02-12 04:21:59.201 ERROR (SyncWorker_7) [xiaomi_gateway] No data in response from hub None
2023-02-12 04:49:49.389 ERROR (MainThread) [homeassistant.components.broadlink.updater] Error fetching s3 (MP1-1K4S at 192.168.1.35) data: [Errno -4000] Network timeout: No response received within 5s
2023-02-12 05:05:16.570 ERROR (MainThread) [aiohttp.server] Error handling request
Traceback (most recent call last):
  File "/usr/local/lib/python3.10/site-packages/aiohttp/web_protocol.py", line 334, in data_received
    messages, upgraded, tail = self._request_parser.feed_data(data)
  File "aiohttp/_http_parser.pyx", line 551, in aiohttp._http_parser.HttpParser.feed_data
aiohttp.http_exceptions.BadStatusLine: 400, message="Bad status line 'Invalid method encountered'"
2023-02-12 05:42:17.320 WARNING (MainThread) [homeassistant.components.websocket_api.http.connection] [547044954016] Disconnected: Did not receive auth message within 10 seconds
2023-02-12 05:52:33.026 ERROR (MainThread) [aiohttp.server] Error handling request
Traceback (most recent call last):
  File "/usr/local/lib/python3.10/site-packages/aiohttp/web_protocol.py", line 334, in data_received
    messages, upgraded, tail = self._request_parser.feed_data(data)
  File "aiohttp/_http_parser.pyx", line 551, in aiohttp._http_parser.HttpParser.feed_data
aiohttp.http_exceptions.BadStatusLine: 400, message="Bad status line 'Invalid method encountered'"
2023-02-12 06:00:00.437 ERROR (MainThread) [homeassistant.components.automation.er_lou_bing_ju_mei_ge_liu_xiao_shi_zhi_xing_kai_guan] 二楼冰柜每隔六小时执行开关: Error executing script. Invalid data for call_service at pos 1: must contain at least one of entity_id, device_id, area_id.
2023-02-12 06:00:00.449 ERROR (MainThread) [homeassistant.components.automation.er_lou_bing_ju_mei_ge_liu_xiao_shi_zhi_xing_kai_guan] Error while executing automation automation.er_lou_bing_ju_mei_ge_liu_xiao_shi_zhi_xing_kai_guan: must contain at least one of entity_id, device_id, area_id.
2023-02-12 06:43:06.419 ERROR (MainThread) [homeassistant.components.broadlink.updater] Error fetching s1 (MP1-1K4S at 192.168.1.33) data: [Errno -4000] Network timeout: No response received within 5s
2023-02-12 07:08:29.796 WARNING (MainThread) [homeassistant.helpers.entity] Update of binary_sensor.door_window_sensor_158d000128fa46 is taking over 10 seconds
2023-02-12 07:08:29.804 ERROR (SyncWorker_3) [xiaomi_gateway] Cannot connect to gateway 286c07f0c4e5
2023-02-12 07:08:29.807 ERROR (SyncWorker_3) [xiaomi_gateway] No data in response from hub None
2023-02-12 07:10:54.386 ERROR (MainThread) [homeassistant.components.broadlink.updater] Error fetching s3 (MP1-1K4S at 192.168.1.35) data: [Errno -4000] Network timeout: No response received within 5s
2023-02-12 07:37:59.387 ERROR (MainThread) [homeassistant.components.broadlink.updater] Error fetching s3 (MP1-1K4S at 192.168.1.35) data: [Errno -4000] Network timeout: No response received within 5s
2023-02-12 07:54:59.965 WARNING (MainThread) [homeassistant.helpers.entity] Update of binary_sensor.door_window_sensor_158d0001a64708 is taking over 10 seconds
2023-02-12 07:54:59.974 ERROR (SyncWorker_1) [xiaomi_gateway] Cannot connect to gateway 286c07f0c4e5
2023-02-12 07:54:59.981 ERROR (SyncWorker_1) [xiaomi_gateway] No data in response from hub None
2023-02-12 08:21:47.273 WARNING (SyncWorker_1) [custom_components.xiaomi_miot.core.xiaomi_cloud] Unauthorized while executing request to https://userprofile.mina.mi.com/device_profile/v2/conversation, logged out.
2023-02-12 08:21:47.285 WARNING (SyncWorker_1) [custom_components.xiaomi_miot.core.xiaomi_cloud] Request xiaomi api: https://userprofile.mina.mi.com/device_profile/v2/conversation {'hardware': 'S12', 'timestamp': 1676161307113, 'limit': 3} failed, response: <!doctype html><html lang="en"><head><title>HTTP Status 401 – Unauthorized</title><style type="text/css">body {font-family:Tahoma,Arial,sans-serif;} h1, h2, h3, b {color:white;background-color:#525D76;} h1 {font-size:22px;} h2 {font-size:16px;} h3 {font-size:14px;} p {font-size:12px;} a {color:black;} .line {height:1px;background-color:#525D76;border:none;}</style></head><body><h1>HTTP Status 401 – Unauthorized</h1></body></html>
2023-02-12 08:23:30.149 ERROR (MainThread) [homeassistant.components.broadlink.updater] Error fetching s2 (MP1-1K4S at 192.168.1.34) data: [Errno -4000] Network timeout: No response received within 5s
2023-02-12 08:24:30.096 WARNING (MainThread) [homeassistant.helpers.entity] Update of binary_sensor.door_window_sensor_158d000128fa46 is taking over 10 seconds
2023-02-12 08:24:30.104 ERROR (SyncWorker_6) [xiaomi_gateway] Cannot connect to gateway 286c07f0c4e5
2023-02-12 08:24:30.111 ERROR (SyncWorker_6) [xiaomi_gateway] No data in response from hub None
2023-02-12 08:31:00.094 WARNING (MainThread) [homeassistant.helpers.entity] Update of switch.plug_158d00015d1bf5 is taking over 10 seconds
2023-02-12 08:31:00.103 ERROR (SyncWorker_6) [xiaomi_gateway] Cannot connect to gateway 286c07f0c4e5
2023-02-12 08:31:00.106 ERROR (SyncWorker_6) [xiaomi_gateway] No data in response from hub None
2023-02-12 08:31:00.188 WARNING (MainThread) [homeassistant.helpers.entity] Update of binary_sensor.door_window_sensor_158d000128fa46 is taking over 10 seconds
2023-02-12 08:31:00.197 ERROR (SyncWorker_7) [xiaomi_gateway] Cannot connect to gateway 286c07f0c4e5
2023-02-12 08:31:00.203 ERROR (SyncWorker_7) [xiaomi_gateway] No data in response from hub None
2023-02-12 08:37:04.387 ERROR (MainThread) [homeassistant.components.broadlink.updater] Error fetching s3 (MP1-1K4S at 192.168.1.35) data: [Errno -4000] Network timeout: No response received within 5s
2023-02-12 08:42:35.149 ERROR (MainThread) [homeassistant.components.broadlink.updater] Error fetching s2 (MP1-1K4S at 192.168.1.34) data: [Errno -4000] Network timeout: No response received within 5s
2023-02-12 08:46:30.164 WARNING (MainThread) [homeassistant.helpers.entity] Update of switch.plug_158d00015d1bf5 is taking over 10 seconds
2023-02-12 08:46:30.173 ERROR (SyncWorker_6) [xiaomi_gateway] Cannot connect to gateway 286c07f0c4e5
2023-02-12 08:46:30.180 ERROR (SyncWorker_6) [xiaomi_gateway] No data in response from hub None
2023-02-12 08:55:00.189 WARNING (MainThread) [homeassistant.helpers.entity] Update of switch.plug_158d00015d1bf5 is taking over 10 seconds
2023-02-12 08:55:00.197 WARNING (MainThread) [homeassistant.helpers.entity] Update of binary_sensor.door_window_sensor_158d0001a64708 is taking over 10 seconds
2023-02-12 08:55:00.199 ERROR (SyncWorker_2) [xiaomi_gateway] Cannot connect to gateway 286c07f0c4e5
2023-02-12 08:55:00.200 ERROR (SyncWorker_3) [xiaomi_gateway] Cannot connect to gateway 286c07f0c4e5
2023-02-12 08:55:00.213 ERROR (SyncWorker_2) [xiaomi_gateway] No data in response from hub None
2023-02-12 08:55:00.219 ERROR (SyncWorker_3) [xiaomi_gateway] No data in response from hub None
2023-02-12 08:55:09.387 ERROR (MainThread) [homeassistant.components.broadlink.updater] Error fetching s3 (MP1-1K4S at 192.168.1.35) data: [Errno -4000] Network timeout: No response received within 5s
2023-02-12 09:00:00.154 WARNING (MainThread) [homeassistant.helpers.service] Unable to find referenced entities switch.er_lou_wo_shi_deng, switch.yi_lou_wo_shi_deng or it is/they are currently not available
2023-02-12 09:03:00.220 WARNING (MainThread) [homeassistant.helpers.entity] Update of switch.plug_158d00015d1bf5 is taking over 10 seconds
2023-02-12 09:03:00.230 ERROR (SyncWorker_2) [xiaomi_gateway] Cannot connect to gateway 286c07f0c4e5
2023-02-12 09:03:00.233 ERROR (SyncWorker_2) [xiaomi_gateway] No data in response from hub None
2023-02-12 09:03:30.222 WARNING (MainThread) [homeassistant.helpers.entity] Update of switch.plug_158d00015d1bf5 is taking over 10 seconds
2023-02-12 09:03:30.233 ERROR (SyncWorker_8) [xiaomi_gateway] Cannot connect to gateway 286c07f0c4e5
2023-02-12 09:03:30.239 ERROR (SyncWorker_8) [xiaomi_gateway] No data in response from hub None
2023-02-12 09:03:30.274 WARNING (MainThread) [homeassistant.helpers.entity] Update of binary_sensor.door_window_sensor_158d000128fa46 is taking over 10 seconds
2023-02-12 09:03:30.283 ERROR (SyncWorker_9) [xiaomi_gateway] Cannot connect to gateway 286c07f0c4e5
2023-02-12 09:03:30.289 ERROR (SyncWorker_9) [xiaomi_gateway] No data in response from hub None
2023-02-12 09:09:40.153 ERROR (MainThread) [homeassistant.components.broadlink.updater] Error fetching s2 (MP1-1K4S at 192.168.1.34) data: [Errno -4000] Network timeout: No response received within 5s
2023-02-12 09:29:30.337 WARNING (MainThread) [homeassistant.helpers.entity] Update of binary_sensor.door_window_sensor_158d000128fa46 is taking over 10 seconds
2023-02-12 09:29:30.346 ERROR (SyncWorker_9) [xiaomi_gateway] Cannot connect to gateway 286c07f0c4e5
2023-02-12 09:29:30.353 ERROR (SyncWorker_9) [xiaomi_gateway] No data in response from hub None
2023-02-12 09:37:12.420 ERROR (MainThread) [homeassistant.components.broadlink.updater] Error fetching s1 (MP1-1K4S at 192.168.1.33) data: [Errno -4000] Network timeout: No response received within 5s
2023-02-12 09:37:27.445 WARNING (MainThread) [homeassistant.helpers.service] Unable to find referenced entities switch.er_lou_wo_shi_deng or it is/they are currently not available
2023-02-12 10:03:00.383 WARNING (MainThread) [homeassistant.helpers.entity] Update of switch.plug_158d00015d1bf5 is taking over 10 seconds
2023-02-12 10:03:00.389 WARNING (MainThread) [homeassistant.helpers.entity] Update of binary_sensor.door_window_sensor_158d0001a64708 is taking over 10 seconds
2023-02-12 10:03:00.396 ERROR (SyncWorker_6) [xiaomi_gateway] Cannot connect to gateway 286c07f0c4e5
2023-02-12 10:03:00.398 ERROR (SyncWorker_0) [xiaomi_gateway] Cannot connect to gateway 286c07f0c4e5
2023-02-12 10:03:00.408 ERROR (SyncWorker_6) [xiaomi_gateway] No data in response from hub None
2023-02-12 10:03:00.411 ERROR (SyncWorker_0) [xiaomi_gateway] No data in response from hub None
2023-02-12 10:15:00.407 WARNING (MainThread) [homeassistant.helpers.entity] Update of switch.plug_158d00015d1bf5 is taking over 10 seconds
2023-02-12 10:15:00.416 ERROR (SyncWorker_2) [xiaomi_gateway] Cannot connect to gateway 286c07f0c4e5
2023-02-12 10:15:00.419 ERROR (SyncWorker_2) [xiaomi_gateway] No data in response from hub None
2023-02-12 10:16:30.410 WARNING (MainThread) [homeassistant.helpers.entity] Update of switch.plug_158d00015d1bf5 is taking over 10 seconds
2023-02-12 10:16:30.419 ERROR (SyncWorker_3) [xiaomi_gateway] Cannot connect to gateway 286c07f0c4e5
2023-02-12 10:16:30.424 ERROR (SyncWorker_3) [xiaomi_gateway] No data in response from hub None
2023-02-12 10:16:30.510 WARNING (MainThread) [homeassistant.helpers.entity] Update of binary_sensor.door_window_sensor_158d000128fa46 is taking over 10 seconds
2023-02-12 10:16:30.519 ERROR (SyncWorker_0) [xiaomi_gateway] Cannot connect to gateway 286c07f0c4e5
2023-02-12 10:16:30.522 ERROR (SyncWorker_0) [xiaomi_gateway] No data in response from hub None
2023-02-12 10:19:00.415 WARNING (MainThread) [homeassistant.helpers.entity] Update of switch.plug_158d00015d1bf5 is taking over 10 seconds
2023-02-12 10:19:00.426 ERROR (SyncWorker_6) [xiaomi_gateway] Cannot connect to gateway 286c07f0c4e5
2023-02-12 10:19:00.434 ERROR (SyncWorker_6) [xiaomi_gateway] No data in response from hub None
2023-02-12 10:22:30.421 WARNING (MainThread) [homeassistant.helpers.entity] Update of switch.plug_158d00015d1bf5 is taking over 10 seconds
2023-02-12 10:22:30.432 ERROR (SyncWorker_9) [xiaomi_gateway] Cannot connect to gateway 286c07f0c4e5
2023-02-12 10:22:30.436 ERROR (SyncWorker_9) [xiaomi_gateway] No data in response from hub None
2023-02-12 10:22:30.437 WARNING (MainThread) [homeassistant.helpers.entity] Update of binary_sensor.door_window_sensor_158d000128fa46 is taking over 10 seconds
2023-02-12 10:22:30.446 ERROR (SyncWorker_6) [xiaomi_gateway] Cannot connect to gateway 286c07f0c4e5
2023-02-12 10:22:30.449 ERROR (SyncWorker_6) [xiaomi_gateway] No data in response from hub None
2023-02-12 10:26:00.430 WARNING (MainThread) [homeassistant.helpers.entity] Update of binary_sensor.door_window_sensor_158d0001a64708 is taking over 10 seconds
2023-02-12 10:26:00.439 ERROR (SyncWorker_5) [xiaomi_gateway] Cannot connect to gateway 286c07f0c4e5
2023-02-12 10:26:00.443 ERROR (SyncWorker_5) [xiaomi_gateway] No data in response from hub None
2023-02-12 10:28:15.516 ERROR (SyncWorker_8) [xiaomi_gateway] Cannot connect to gateway 286c07f0c4e5
2023-02-12 10:28:15.520 ERROR (SyncWorker_8) [xiaomi_gateway] No data in response from hub None
2023-02-12 10:35:00.448 WARNING (MainThread) [homeassistant.helpers.entity] Update of switch.plug_158d00015d1bf5 is taking over 10 seconds
2023-02-12 10:35:00.459 ERROR (SyncWorker_0) [xiaomi_gateway] Cannot connect to gateway 286c07f0c4e5
2023-02-12 10:35:00.463 ERROR (SyncWorker_0) [xiaomi_gateway] No data in response from hub None
2023-02-12 10:35:15.387 ERROR (MainThread) [homeassistant.components.broadlink.updater] Error fetching s3 (MP1-1K4S at 192.168.1.35) data: [Errno -4000] Network timeout: No response received within 5s
2023-02-12 10:37:00.454 WARNING (MainThread) [homeassistant.helpers.entity] Update of binary_sensor.door_window_sensor_158d0001a64708 is taking over 10 seconds
2023-02-12 10:37:00.462 ERROR (SyncWorker_4) [xiaomi_gateway] Cannot connect to gateway 286c07f0c4e5
2023-02-12 10:37:00.466 ERROR (SyncWorker_4) [xiaomi_gateway] No data in response from hub None
2023-02-12 10:37:10.471 WARNING (MainThread) [homeassistant.helpers.entity] Update of binary_sensor.door_window_sensor_158d000128fa46 is taking over 10 seconds
2023-02-12 10:37:10.479 ERROR (SyncWorker_9) [xiaomi_gateway] Cannot connect to gateway 286c07f0c4e5
2023-02-12 10:37:10.482 ERROR (SyncWorker_9) [xiaomi_gateway] No data in response from hub None
2023-02-12 11:01:00.506 WARNING (MainThread) [homeassistant.helpers.entity] Update of switch.plug_158d00015d1bf5 is taking over 10 seconds
2023-02-12 11:01:00.516 ERROR (SyncWorker_1) [xiaomi_gateway] Cannot connect to gateway 286c07f0c4e5
2023-02-12 11:01:00.518 ERROR (SyncWorker_1) [xiaomi_gateway] No data in response from hub None
2023-02-12 11:03:00.513 WARNING (MainThread) [homeassistant.helpers.entity] Update of switch.plug_158d00015d1bf5 is taking over 10 seconds
2023-02-12 11:03:00.520 WARNING (MainThread) [homeassistant.helpers.entity] Update of binary_sensor.door_window_sensor_158d0001a64708 is taking over 10 seconds
2023-02-12 11:03:00.522 ERROR (SyncWorker_4) [xiaomi_gateway] Cannot connect to gateway 286c07f0c4e5
2023-02-12 11:03:00.523 ERROR (SyncWorker_3) [xiaomi_gateway] Cannot connect to gateway 286c07f0c4e5
2023-02-12 11:03:00.533 ERROR (SyncWorker_4) [xiaomi_gateway] No data in response from hub None
2023-02-12 11:03:00.538 ERROR (SyncWorker_3) [xiaomi_gateway] No data in response from hub None
2023-02-12 11:04:00.514 WARNING (MainThread) [homeassistant.helpers.entity] Update of binary_sensor.door_window_sensor_158d0001a64708 is taking over 10 seconds
2023-02-12 11:04:00.522 ERROR (SyncWorker_4) [xiaomi_gateway] Cannot connect to gateway 286c07f0c4e5
2023-02-12 11:04:00.528 ERROR (SyncWorker_4) [xiaomi_gateway] No data in response from hub None
2023-02-12 11:33:00.587 WARNING (MainThread) [homeassistant.helpers.entity] Update of switch.plug_158d00015d1bf5 is taking over 10 seconds
2023-02-12 11:33:00.592 WARNING (MainThread) [homeassistant.helpers.entity] Update of binary_sensor.door_window_sensor_158d0001a64708 is taking over 10 seconds
2023-02-12 11:33:00.599 ERROR (SyncWorker_8) [xiaomi_gateway] Cannot connect to gateway 286c07f0c4e5
2023-02-12 11:33:00.600 ERROR (SyncWorker_3) [xiaomi_gateway] Cannot connect to gateway 286c07f0c4e5
2023-02-12 11:33:00.604 ERROR (SyncWorker_8) [xiaomi_gateway] No data in response from hub None
2023-02-12 11:33:00.608 ERROR (SyncWorker_3) [xiaomi_gateway] No data in response from hub None
2023-02-12 11:37:30.602 WARNING (MainThread) [homeassistant.helpers.entity] Update of binary_sensor.door_window_sensor_158d0001a64708 is taking over 10 seconds
2023-02-12 11:37:30.609 ERROR (SyncWorker_1) [xiaomi_gateway] Cannot connect to gateway 286c07f0c4e5
2023-02-12 11:37:30.612 ERROR (SyncWorker_1) [xiaomi_gateway] No data in response from hub None
2023-02-12 11:39:00.600 WARNING (MainThread) [homeassistant.helpers.entity] Update of switch.plug_158d00015d1bf5 is taking over 10 seconds
2023-02-12 11:39:00.609 ERROR (SyncWorker_0) [xiaomi_gateway] Cannot connect to gateway 286c07f0c4e5
2023-02-12 11:39:00.612 ERROR (SyncWorker_0) [xiaomi_gateway] No data in response from hub None
2023-02-12 11:43:30.608 WARNING (MainThread) [homeassistant.helpers.entity] Update of switch.plug_158d00015d1bf5 is taking over 10 seconds
2023-02-12 11:43:30.613 WARNING (MainThread) [homeassistant.helpers.entity] Update of binary_sensor.door_window_sensor_158d0001a64708 is taking over 10 seconds
2023-02-12 11:43:30.616 ERROR (SyncWorker_7) [xiaomi_gateway] Cannot connect to gateway 286c07f0c4e5
2023-02-12 11:43:30.620 ERROR (SyncWorker_7) [xiaomi_gateway] No data in response from hub None
2023-02-12 11:43:30.622 ERROR (SyncWorker_2) [xiaomi_gateway] Cannot connect to gateway 286c07f0c4e5
2023-02-12 11:43:30.628 ERROR (SyncWorker_2) [xiaomi_gateway] No data in response from hub None
2023-02-12 11:45:17.420 ERROR (MainThread) [homeassistant.components.broadlink.updater] Error fetching s1 (MP1-1K4S at 192.168.1.33) data: [Errno -4000] Network timeout: No response received within 5s
2023-02-12 12:00:00.445 ERROR (MainThread) [homeassistant.components.automation.er_lou_bing_ju_mei_ge_liu_xiao_shi_zhi_xing_kai_guan] 二楼冰柜每隔六小时执行开关: Error executing script. Invalid data for call_service at pos 1: must contain at least one of entity_id, device_id, area_id.
2023-02-12 12:00:00.480 ERROR (MainThread) [homeassistant.components.automation.er_lou_bing_ju_mei_ge_liu_xiao_shi_zhi_xing_kai_guan] Error while executing automation automation.er_lou_bing_ju_mei_ge_liu_xiao_shi_zhi_xing_kai_guan: must contain at least one of entity_id, device_id, area_id.
2023-02-12 12:00:00.518 ERROR (MainThread) [homeassistant.components.automation.edge_ttsce_shi] edge_tts测试: Error executing script. Unexpected error for call_service at pos 1: Expecting value: line 1 column 1 (char 0)
Traceback (most recent call last):
  File "/usr/src/homeassistant/homeassistant/helpers/script.py", line 451, in _async_step
    await getattr(self, handler)()
  File "/usr/src/homeassistant/homeassistant/helpers/script.py", line 684, in _async_call_service_step
    await service_task
  File "/usr/src/homeassistant/homeassistant/core.py", line 1787, in async_call
    task.result()
  File "/usr/src/homeassistant/homeassistant/core.py", line 1824, in _execute_service
    await cast(Callable[[ServiceCall], Awaitable[None]], handler.job.target)(
  File "/usr/src/homeassistant/homeassistant/components/tts/__init__.py", line 217, in async_say_handle
    await hass.services.async_call(
  File "/usr/src/homeassistant/homeassistant/core.py", line 1787, in async_call
    task.result()
  File "/usr/src/homeassistant/homeassistant/core.py", line 1824, in _execute_service
    await cast(Callable[[ServiceCall], Awaitable[None]], handler.job.target)(
  File "/usr/src/homeassistant/homeassistant/helpers/entity_component.py", line 213, in handle_service
    await service.entity_service_call(
  File "/usr/src/homeassistant/homeassistant/helpers/service.py", line 680, in entity_service_call
    future.result()  # pop exception if have
  File "/usr/src/homeassistant/homeassistant/helpers/entity.py", line 968, in async_request_call
    await coro
  File "/usr/src/homeassistant/homeassistant/helpers/service.py", line 720, in _handle_entity_call
    await result
  File "/usr/src/homeassistant/homeassistant/components/media_player/__init__.py", line 791, in async_play_media
    await self.hass.async_add_executor_job(
  File "/usr/local/lib/python3.10/concurrent/futures/thread.py", line 58, in run
    result = self.fn(*self.args, **self.kwargs)
  File "/usr/src/homeassistant/homeassistant/components/plex/media_player.py", line 489, in play_media
    result = process_plex_payload(
  File "/usr/src/homeassistant/homeassistant/components/plex/services.py", line 145, in process_plex_payload
    content = json.loads(content_id)
  File "/usr/local/lib/python3.10/json/__init__.py", line 346, in loads
    return _default_decoder.decode(s)
  File "/usr/local/lib/python3.10/json/decoder.py", line 337, in decode
    obj, end = self.raw_decode(s, idx=_w(s, 0).end())
  File "/usr/local/lib/python3.10/json/decoder.py", line 355, in raw_decode
    raise JSONDecodeError("Expecting value", s, err.value) from None
json.decoder.JSONDecodeError: Expecting value: line 1 column 1 (char 0)
2023-02-12 12:00:00.542 ERROR (MainThread) [homeassistant.components.automation.edge_ttsce_shi] While executing automation automation.edge_ttsce_shi
Traceback (most recent call last):
  File "/usr/src/homeassistant/homeassistant/components/automation/__init__.py", line 546, in async_trigger
    await self.action_script.async_run(
  File "/usr/src/homeassistant/homeassistant/helpers/script.py", line 1524, in async_run
    await asyncio.shield(run.async_run())
  File "/usr/src/homeassistant/homeassistant/helpers/script.py", line 409, in async_run
    await self._async_step(log_exceptions=False)
  File "/usr/src/homeassistant/homeassistant/helpers/script.py", line 453, in _async_step
    self._handle_exception(
  File "/usr/src/homeassistant/homeassistant/helpers/script.py", line 476, in _handle_exception
    raise exception
  File "/usr/src/homeassistant/homeassistant/helpers/script.py", line 451, in _async_step
    await getattr(self, handler)()
  File "/usr/src/homeassistant/homeassistant/helpers/script.py", line 684, in _async_call_service_step
    await service_task
  File "/usr/src/homeassistant/homeassistant/core.py", line 1787, in async_call
    task.result()
  File "/usr/src/homeassistant/homeassistant/core.py", line 1824, in _execute_service
    await cast(Callable[[ServiceCall], Awaitable[None]], handler.job.target)(
  File "/usr/src/homeassistant/homeassistant/components/tts/__init__.py", line 217, in async_say_handle
    await hass.services.async_call(
  File "/usr/src/homeassistant/homeassistant/core.py", line 1787, in async_call
    task.result()
  File "/usr/src/homeassistant/homeassistant/core.py", line 1824, in _execute_service
    await cast(Callable[[ServiceCall], Awaitable[None]], handler.job.target)(
  File "/usr/src/homeassistant/homeassistant/helpers/entity_component.py", line 213, in handle_service
    await service.entity_service_call(
  File "/usr/src/homeassistant/homeassistant/helpers/service.py", line 680, in entity_service_call
    future.result()  # pop exception if have
  File "/usr/src/homeassistant/homeassistant/helpers/entity.py", line 968, in async_request_call
    await coro
  File "/usr/src/homeassistant/homeassistant/helpers/service.py", line 720, in _handle_entity_call
    await result
  File "/usr/src/homeassistant/homeassistant/components/media_player/__init__.py", line 791, in async_play_media
    await self.hass.async_add_executor_job(
  File "/usr/local/lib/python3.10/concurrent/futures/thread.py", line 58, in run
    result = self.fn(*self.args, **self.kwargs)
  File "/usr/src/homeassistant/homeassistant/components/plex/media_player.py", line 489, in play_media
    result = process_plex_payload(
  File "/usr/src/homeassistant/homeassistant/components/plex/services.py", line 145, in process_plex_payload
    content = json.loads(content_id)
  File "/usr/local/lib/python3.10/json/__init__.py", line 346, in loads
    return _default_decoder.decode(s)
  File "/usr/local/lib/python3.10/json/decoder.py", line 337, in decode
    obj, end = self.raw_decode(s, idx=_w(s, 0).end())
  File "/usr/local/lib/python3.10/json/decoder.py", line 355, in raw_decode
    raise JSONDecodeError("Expecting value", s, err.value) from None
json.decoder.JSONDecodeError: Expecting value: line 1 column 1 (char 0)
2023-02-12 12:03:47.884 ERROR (Thread-1624 (_connect)) [plexapi] http://192.168.1.6:32500: HTTPConnectionPool(host='192.168.1.6', port=32500): Max retries exceeded with url: /resources (Caused by NewConnectionError('<urllib3.connection.HTTPConnection object at 0x7f4dafeaa0>: Failed to establish a new connection: [Errno 113] Host is unreachable'))
2023-02-12 12:03:47.885 ERROR (Thread-1623 (_connect)) [plexapi] http://192.168.1.6:32500: HTTPConnectionPool(host='192.168.1.6', port=32500): Max retries exceeded with url: /resources (Caused by NewConnectionError('<urllib3.connection.HTTPConnection object at 0x7f7d402050>: Failed to establish a new connection: [Errno 113] Host is unreachable'))
2023-02-12 12:03:47.902 ERROR (SyncWorker_3) [homeassistant.components.plex.server] Resource connection failed to plex.tv: p2301
2023-02-12 12:05:00.667 WARNING (MainThread) [homeassistant.helpers.entity] Update of switch.plug_158d00015d1bf5 is taking over 10 seconds
2023-02-12 12:05:00.679 ERROR (SyncWorker_7) [xiaomi_gateway] Cannot connect to gateway 286c07f0c4e5
2023-02-12 12:05:00.683 ERROR (SyncWorker_7) [xiaomi_gateway] No data in response from hub None
2023-02-12 12:21:45.150 ERROR (MainThread) [homeassistant.components.broadlink.updater] Error fetching s2 (MP1-1K4S at 192.168.1.34) data: [Errno -4000] Network timeout: No response received within 5s
2023-02-12 12:38:00.783 WARNING (MainThread) [homeassistant.helpers.entity] Update of binary_sensor.door_window_sensor_158d000128fa46 is taking over 10 seconds
2023-02-12 12:38:00.792 ERROR (SyncWorker_1) [xiaomi_gateway] Cannot connect to gateway 286c07f0c4e5
2023-02-12 12:38:00.798 ERROR (SyncWorker_1) [xiaomi_gateway] No data in response from hub None
2023-02-12 13:05:50.149 ERROR (MainThread) [homeassistant.components.broadlink.updater] Error fetching s2 (MP1-1K4S at 192.168.1.34) data: [Errno -4000] Network timeout: No response received within 5s
2023-02-12 13:24:30.908 WARNING (MainThread) [homeassistant.helpers.entity] Update of binary_sensor.door_window_sensor_158d000128fa46 is taking over 10 seconds
2023-02-12 13:24:30.917 ERROR (SyncWorker_4) [xiaomi_gateway] Cannot connect to gateway 286c07f0c4e5
2023-02-12 13:24:30.920 ERROR (SyncWorker_4) [xiaomi_gateway] No data in response from hub None
2023-02-12 13:51:00.963 WARNING (MainThread) [homeassistant.helpers.entity] Update of binary_sensor.door_window_sensor_158d0001a64708 is taking over 10 seconds
2023-02-12 13:51:00.972 ERROR (SyncWorker_1) [xiaomi_gateway] Cannot connect to gateway 286c07f0c4e5
2023-02-12 13:51:00.978 ERROR (SyncWorker_1) [xiaomi_gateway] No data in response from hub None
2023-02-12 14:34:55.148 ERROR (MainThread) [homeassistant.components.broadlink.updater] Error fetching s2 (MP1-1K4S at 192.168.1.34) data: [Errno -4000] Network timeout: No response received within 5s
2023-02-12 14:46:20.386 ERROR (MainThread) [homeassistant.components.broadlink.updater] Error fetching s3 (MP1-1K4S at 192.168.1.35) data: [Errno -4000] Network timeout: No response received within 5s
2023-02-12 14:46:24.423 ERROR (MainThread) [homeassistant.components.broadlink.updater] Error fetching s1 (MP1-1K4S at 192.168.1.33) data: [Errno -4000] Network timeout: No response received within 5s
2023-02-12 15:31:00.150 ERROR (MainThread) [homeassistant.components.broadlink.updater] Error fetching s2 (MP1-1K4S at 192.168.1.34) data: [Errno -4000] Network timeout: No response received within 5s
2023-02-12 15:49:01.345 WARNING (MainThread) [homeassistant.helpers.entity] Update of binary_sensor.door_window_sensor_158d000128fa46 is taking over 10 seconds
2023-02-12 15:49:01.351 ERROR (SyncWorker_4) [xiaomi_gateway] Cannot connect to gateway 286c07f0c4e5
2023-02-12 15:49:01.357 ERROR (SyncWorker_4) [xiaomi_gateway] No data in response from hub None
2023-02-12 16:00:17.728 ERROR (MainThread) [frontend.js.latest.202302020] :0:0 Script error.
2023-02-12 16:00:49.351 ERROR (MainThread) [frontend.js.latest.202302020] :0:0 Script error.
2023-02-12 16:12:01.337 WARNING (MainThread) [homeassistant.helpers.entity] Update of binary_sensor.door_window_sensor_158d0001a64708 is taking over 10 seconds
2023-02-12 16:12:01.347 ERROR (SyncWorker_2) [xiaomi_gateway] Cannot connect to gateway 286c07f0c4e5
2023-02-12 16:12:01.354 ERROR (SyncWorker_2) [xiaomi_gateway] No data in response from hub None
2023-02-12 16:39:32.422 ERROR (MainThread) [homeassistant.components.broadlink.updater] Error fetching s1 (MP1-1K4S at 192.168.1.33) data: [Errno -4000] Network timeout: No response received within 5s
2023-02-12 17:06:01.480 WARNING (MainThread) [homeassistant.helpers.entity] Update of binary_sensor.door_window_sensor_158d0001a64708 is taking over 10 seconds
2023-02-12 17:06:01.490 ERROR (SyncWorker_0) [xiaomi_gateway] Cannot connect to gateway 286c07f0c4e5
2023-02-12 17:06:01.496 ERROR (SyncWorker_0) [xiaomi_gateway] No data in response from hub None
2023-02-12 17:06:31.483 WARNING (MainThread) [homeassistant.helpers.entity] Update of binary_sensor.door_window_sensor_158d0001a64708 is taking over 10 seconds
2023-02-12 17:06:31.491 ERROR (SyncWorker_8) [xiaomi_gateway] Cannot connect to gateway 286c07f0c4e5
2023-02-12 17:06:31.498 ERROR (SyncWorker_8) [xiaomi_gateway] No data in response from hub None
2023-02-12 17:37:21.984 ERROR (MainThread) [aiohttp.server] Error handling request
Traceback (most recent call last):
  File "/usr/local/lib/python3.10/site-packages/aiohttp/web_protocol.py", line 334, in data_received
    messages, upgraded, tail = self._request_parser.feed_data(data)
  File "aiohttp/_http_parser.pyx", line 551, in aiohttp._http_parser.HttpParser.feed_data
aiohttp.http_exceptions.BadStatusLine: 400, message="Bad status line 'Invalid method encountered'"
2023-02-12 17:37:22.980 ERROR (MainThread) [aiohttp.server] Error handling request
Traceback (most recent call last):
  File "/usr/local/lib/python3.10/site-packages/aiohttp/web_protocol.py", line 334, in data_received
    messages, upgraded, tail = self._request_parser.feed_data(data)
  File "aiohttp/_http_parser.pyx", line 551, in aiohttp._http_parser.HttpParser.feed_data
aiohttp.http_exceptions.BadStatusLine: 400, message="Bad status line 'Invalid method encountered'"
2023-02-12 17:41:06.149 ERROR (MainThread) [homeassistant.components.broadlink.updater] Error fetching s2 (MP1-1K4S at 192.168.1.34) data: [Errno -4000] Network timeout: No response received within 5s
2023-02-12 18:00:00.495 ERROR (MainThread) [homeassistant.components.automation.er_lou_bing_ju_mei_ge_liu_xiao_shi_zhi_xing_kai_guan] 二楼冰柜每隔六小时执行开关: Error executing script. Invalid data for call_service at pos 1: must contain at least one of entity_id, device_id, area_id.
2023-02-12 18:00:00.528 ERROR (MainThread) [homeassistant.components.automation.er_lou_bing_ju_mei_ge_liu_xiao_shi_zhi_xing_kai_guan] Error while executing automation automation.er_lou_bing_ju_mei_ge_liu_xiao_shi_zhi_xing_kai_guan: must contain at least one of entity_id, device_id, area_id.
2023-02-12 19:25:01.870 WARNING (MainThread) [homeassistant.helpers.entity] Update of switch.plug_158d00015d1bf5 is taking over 10 seconds
2023-02-12 19:25:01.879 ERROR (SyncWorker_2) [xiaomi_gateway] Cannot connect to gateway 286c07f0c4e5
2023-02-12 19:25:01.886 ERROR (SyncWorker_2) [xiaomi_gateway] No data in response from hub None
2023-02-12 19:25:37.421 ERROR (MainThread) [homeassistant.components.broadlink.updater] Error fetching s1 (MP1-1K4S at 192.168.1.33) data: [Errno -4000] Network timeout: No response received within 5s
2023-02-12 20:17:32.037 ERROR (SyncWorker_4) [xiaomi_gateway] Cannot connect to gateway 286c07f0c4e5
2023-02-12 20:17:32.048 WARNING (MainThread) [homeassistant.helpers.entity] Update of binary_sensor.door_window_sensor_158d0001a64708 is taking over 10 seconds
2023-02-12 20:17:32.056 ERROR (SyncWorker_4) [xiaomi_gateway] No data in response from hub None
2023-02-12 20:18:18.878 WARNING (DHCPWatcher) [scapy.runtime] Socket <scapy.arch.linux.L2ListenSocket object at 0x7f940b1a20> failed with '[Errno 100] Network is down'. It was closed.
2023-02-12 20:18:20.386 WARNING (MainThread) [homeassistant.components.broadlink.updater] Disconnected from s3 (MP1-1K4S at 192.168.1.35)
2023-02-12 20:18:20.395 ERROR (MainThread) [homeassistant.components.broadlink.updater] Error fetching s3 (MP1-1K4S at 192.168.1.35) data: [Errno 101] Network unreachable
