2023-02-09 15:10:10.327 WARNING (SyncWorker_3) [homeassistant.loader] We found a custom integration hello_miai which has not been tested by Home Assistant. This component might cause stability problems, be sure to disable it if you experience issues with Home Assistant
2023-02-09 15:10:10.333 WARNING (SyncWorker_3) [homeassistant.loader] We found a custom integration xiaomi_miot_raw which has not been tested by Home Assistant. This component might cause stability problems, be sure to disable it if you experience issues with Home Assistant
2023-02-09 15:10:10.337 WARNING (SyncWorker_3) [homeassistant.loader] We found a custom integration colorfulclouds which has not been tested by Home Assistant. This component might cause stability problems, be sure to disable it if you experience issues with Home Assistant
2023-02-09 15:10:10.340 WARNING (SyncWorker_3) [homeassistant.loader] We found a custom integration hacs which has not been tested by Home Assistant. This component might cause stability problems, be sure to disable it if you experience issues with Home Assistant
2023-02-09 15:10:10.343 WARNING (SyncWorker_3) [homeassistant.loader] We found a custom integration heweather_hourlyforecast which has not been tested by Home Assistant. This component might cause stability problems, be sure to disable it if you experience issues with Home Assistant
2023-02-09 15:10:10.347 WARNING (SyncWorker_3) [homeassistant.loader] We found a custom integration edge_tts which has not been tested by Home Assistant. This component might cause stability problems, be sure to disable it if you experience issues with Home Assistant
2023-02-09 15:10:10.350 WARNING (SyncWorker_3) [homeassistant.loader] We found a custom integration xiaomi_miot which has not been tested by Home Assistant. This component might cause stability problems, be sure to disable it if you experience issues with Home Assistant
2023-02-09 15:10:10.353 WARNING (SyncWorker_3) [homeassistant.loader] We found a custom integration huawei_mesh_router which has not been tested by Home Assistant. This component might cause stability problems, be sure to disable it if you experience issues with Home Assistant
2023-02-09 15:10:10.355 WARNING (SyncWorker_3) [homeassistant.loader] We found a custom integration lifesuggestion which has not been tested by Home Assistant. This component might cause stability problems, be sure to disable it if you experience issues with Home Assistant
2023-02-09 15:10:10.359 WARNING (SyncWorker_3) [homeassistant.loader] We found a custom integration xiaomi_gateway3 which has not been tested by Home Assistant. This component might cause stability problems, be sure to disable it if you experience issues with Home Assistant
2023-02-09 15:10:10.362 WARNING (SyncWorker_3) [homeassistant.loader] We found a custom integration heweather which has not been tested by Home Assistant. This component might cause stability problems, be sure to disable it if you experience issues with Home Assistant
2023-02-09 15:10:10.366 WARNING (SyncWorker_3) [homeassistant.loader] We found a custom integration heweather_forecast which has not been tested by Home Assistant. This component might cause stability problems, be sure to disable it if you experience issues with Home Assistant
2023-02-09 15:10:10.369 WARNING (SyncWorker_3) [homeassistant.loader] We found a custom integration hasslife which has not been tested by Home Assistant. This component might cause stability problems, be sure to disable it if you experience issues with Home Assistant
2023-02-09 15:10:19.045 WARNING (MainThread) [homeassistant.components.weather] custom_components.heweather_forecast.weather::LocalWeather is overriding deprecated methods on an instance of WeatherEntity, this is not valid and will be unsupported from Home Assistant 2023.1. Please report it to the custom integration author.
2023-02-09 15:10:19.262 WARNING (SyncWorker_2) [custom_components.hello_miai] list index out of range
2023-02-09 15:10:19.280 WARNING (SyncWorker_2) [custom_components.hello_miai] get_sign Failed
2023-02-09 15:10:28.454 WARNING (MainThread) [homeassistant.components.switch] Platform broadlink not ready yet: None; Retrying in background in 30 seconds
2023-02-09 15:10:32.081 WARNING (MainThread) [custom_components.xiaomi_miot] None device in xiaomi cloud: 15513084760
2023-02-09 15:10:32.494 WARNING (MainThread) [homeassistant.config_entries] Config entry 'Wi-Fi智能插座' for broadlink integration not ready yet: [Errno -4000] Network timeout: No response received within 5s; Retrying in background
2023-02-09 15:10:37.354 WARNING (MainThread) [homeassistant.config_entries] Config entry 'SP-MINI' for broadlink integration not ready yet: [Errno -4000] Network timeout: No response received within 10s; Retrying in background
2023-02-09 15:10:45.696 WARNING (MainThread) [homeassistant.config_entries] Config entry 'SpeedTest' for speedtestdotnet integration not ready yet: <urlopen error timed out>; Retrying in background
2023-02-09 15:10:49.596 ERROR (MainThread) [homeassistant.components.homekit.util] media_player.plex_plex_for_windows_x13 does not support any media_player features
2023-02-09 15:10:49.621 ERROR (MainThread) [homeassistant.components.homekit.util] media_player.plex_plex_for_kodi_kodi1 does not support any media_player features
2023-02-09 15:10:49.628 ERROR (MainThread) [homeassistant.components.homekit.util] media_player.plex_plex_web_microsoft_edge_windows does not support any media_player features
2023-02-09 15:30:42.019 WARNING (MainThread) [homeassistant.helpers.entity] Update of switch.plug_158d00015d1bf5 is taking over 10 seconds
2023-02-09 15:30:42.027 ERROR (SyncWorker_10) [xiaomi_gateway] Cannot connect to gateway 286c07f0c4e5
2023-02-09 15:30:42.043 ERROR (SyncWorker_10) [xiaomi_gateway] No data in response from hub None
2023-02-09 15:47:42.242 WARNING (MainThread) [homeassistant.helpers.entity] Update of binary_sensor.door_window_sensor_158d000128fa46 is taking over 10 seconds
2023-02-09 15:47:42.250 ERROR (SyncWorker_4) [xiaomi_gateway] Cannot connect to gateway 286c07f0c4e5
2023-02-09 15:47:42.255 ERROR (SyncWorker_4) [xiaomi_gateway] No data in response from hub None
2023-02-09 16:20:34.362 ERROR (MainThread) [homeassistant.components.broadlink.updater] Error fetching s3 (MP1-1K4S at 192.168.1.35) data: [Errno -4000] Network timeout: No response received within 5s
2023-02-09 16:53:59.116 WARNING (MainThread) [homeassistant.helpers.service] Unable to find referenced entities switch.er_lou_wo_shi_deng or it is/they are currently not available
2023-02-09 16:57:05.649 ERROR (MainThread) [homeassistant.components.speedtestdotnet.coordinator] Error fetching speedtestdotnet data: Unable to connect to servers to test latency.
2023-02-09 17:20:39.363 ERROR (MainThread) [homeassistant.components.broadlink.updater] Error fetching s3 (MP1-1K4S at 192.168.1.35) data: [Errno -4000] Network timeout: No response received within 5s
2023-02-09 17:31:54.325 ERROR (MainThread) [aiohttp.server] Error handling request
Traceback (most recent call last):
  File "/usr/local/lib/python3.10/site-packages/aiohttp/web_protocol.py", line 334, in data_received
    messages, upgraded, tail = self._request_parser.feed_data(data)
  File "aiohttp/_http_parser.pyx", line 551, in aiohttp._http_parser.HttpParser.feed_data
aiohttp.http_exceptions.BadStatusLine: 400, message="Bad status line 'Invalid method encountered'"
2023-02-09 17:31:54.337 ERROR (MainThread) [aiohttp.server] Error handling request
Traceback (most recent call last):
  File "/usr/local/lib/python3.10/site-packages/aiohttp/web_protocol.py", line 334, in data_received
    messages, upgraded, tail = self._request_parser.feed_data(data)
  File "aiohttp/_http_parser.pyx", line 551, in aiohttp._http_parser.HttpParser.feed_data
aiohttp.http_exceptions.BadStatusLine: 400, message="Bad status line 'Invalid method encountered'"
2023-02-09 18:00:00.481 ERROR (MainThread) [homeassistant.components.automation.er_lou_bing_ju_mei_ge_liu_xiao_shi_zhi_xing_kai_guan] 二楼冰柜每隔六小时执行开关: Error executing script. Invalid data for call_service at pos 1: must contain at least one of entity_id, device_id, area_id.
2023-02-09 18:00:00.511 ERROR (MainThread) [homeassistant.components.automation.er_lou_bing_ju_mei_ge_liu_xiao_shi_zhi_xing_kai_guan] Error while executing automation automation.er_lou_bing_ju_mei_ge_liu_xiao_shi_zhi_xing_kai_guan: must contain at least one of entity_id, device_id, area_id.
2023-02-09 18:14:12.738 WARNING (MainThread) [homeassistant.helpers.entity] Update of binary_sensor.door_window_sensor_158d000128fa46 is taking over 10 seconds
2023-02-09 18:14:12.745 ERROR (SyncWorker_1) [xiaomi_gateway] Cannot connect to gateway 286c07f0c4e5
2023-02-09 18:14:12.752 ERROR (SyncWorker_1) [xiaomi_gateway] No data in response from hub None
2023-02-09 18:17:44.101 ERROR (MainThread) [homeassistant.components.broadlink.updater] Error fetching s1 (MP1-1K4S at 192.168.1.33) data: [Errno -4000] Network timeout: No response received within 5s
2023-02-09 18:22:51.649 ERROR (MainThread) [homeassistant.components.automation.chi_kai_tong_zhi] 离开通知: Error executing script. Invalid data for call_service at pos 1: expected dict for dictionary value @ data['data']
2023-02-09 18:22:51.663 ERROR (MainThread) [homeassistant.components.automation.chi_kai_tong_zhi] Error while executing automation automation.chi_kai_tong_zhi: expected dict for dictionary value @ data['data']
2023-02-09 18:46:12.781 WARNING (MainThread) [homeassistant.helpers.entity] Update of binary_sensor.door_window_sensor_158d0001a64708 is taking over 10 seconds
2023-02-09 18:46:12.792 ERROR (SyncWorker_11) [xiaomi_gateway] Cannot connect to gateway 286c07f0c4e5
2023-02-09 18:46:12.799 ERROR (SyncWorker_11) [xiaomi_gateway] No data in response from hub None
2023-02-09 18:57:12.829 WARNING (MainThread) [homeassistant.helpers.entity] Update of binary_sensor.door_window_sensor_158d000128fa46 is taking over 10 seconds
2023-02-09 18:57:12.839 ERROR (SyncWorker_10) [xiaomi_gateway] Cannot connect to gateway 286c07f0c4e5
2023-02-09 18:57:12.845 ERROR (SyncWorker_10) [xiaomi_gateway] No data in response from hub None
2023-02-09 19:00:12.817 WARNING (MainThread) [homeassistant.helpers.entity] Update of switch.plug_158d00015d1bf5 is taking over 10 seconds
2023-02-09 19:00:12.836 WARNING (MainThread) [homeassistant.helpers.entity] Update of binary_sensor.door_window_sensor_158d0001a64708 is taking over 10 seconds
2023-02-09 19:00:12.854 ERROR (SyncWorker_0) [xiaomi_gateway] Cannot connect to gateway 286c07f0c4e5
2023-02-09 19:00:12.866 ERROR (SyncWorker_0) [xiaomi_gateway] No data in response from hub None
2023-02-09 19:00:12.925 ERROR (SyncWorker_8) [xiaomi_gateway] Cannot connect to gateway 286c07f0c4e5
2023-02-09 19:00:12.930 ERROR (SyncWorker_8) [xiaomi_gateway] No data in response from hub None
2023-02-09 19:04:58.530 WARNING (MainThread) [homeassistant.components.automation.hui_jia_xiang_ling] 回家响铃: Already running
2023-02-09 19:04:58.559 ERROR (SyncWorker_0) [custom_components.hello_miai] 还未登录
2023-02-09 19:05:27.238 WARNING (MainThread) [homeassistant.components.automation.hui_jia_xiang_ling] 回家响铃: Already running
2023-02-09 19:10:12.849 WARNING (MainThread) [homeassistant.helpers.entity] Update of binary_sensor.door_window_sensor_158d0001a64708 is taking over 10 seconds
2023-02-09 19:10:12.859 ERROR (SyncWorker_8) [xiaomi_gateway] Cannot connect to gateway 286c07f0c4e5
2023-02-09 19:10:12.865 ERROR (SyncWorker_8) [xiaomi_gateway] No data in response from hub None
2023-02-09 19:14:13.414 WARNING (MainThread) [homeassistant.helpers.entity] Update of binary_sensor.door_window_sensor_158d000128fa46 is taking over 10 seconds
2023-02-09 19:14:13.422 ERROR (SyncWorker_2) [xiaomi_gateway] Cannot connect to gateway 286c07f0c4e5
2023-02-09 19:14:13.428 ERROR (SyncWorker_2) [xiaomi_gateway] No data in response from hub None
2023-02-09 19:23:48.169 WARNING (MainThread) [async_upnp_client.profiles.profile] Failed (re-)subscribing to: uuid:2169e641-ab6f-4504-8f8b-51305a2f8957, reason: UpnpConnectionError('ClientConnectorError(ConnectionKey(host=\'192.168.1.30\', port=9999, is_ssl=False, ssl=None, proxy=None, proxy_auth=None, proxy_headers_hash=6482299065325415443), OSError(113, "Connect call failed (\'192.168.1.30\', 9999)"))', None)
2023-02-09 19:23:57.288 WARNING (MainThread) [async_upnp_client.profiles.profile] Failed (re-)subscribing to: uuid:9e77af05-0630-45aa-b2ef-3d5438bbc6fa, reason: UpnpConnectionError('ClientConnectorError(ConnectionKey(host=\'192.168.1.30\', port=9999, is_ssl=False, ssl=None, proxy=None, proxy_auth=None, proxy_headers_hash=6482299065325415443), OSError(113, "Connect call failed (\'192.168.1.30\', 9999)"))', None)
2023-02-09 19:24:06.931 WARNING (MainThread) [homeassistant.components.media_player] Updating dlna_dmr media_player took longer than the scheduled update interval 0:00:10
2023-02-09 19:24:06.936 WARNING (MainThread) [homeassistant.helpers.entity] Update of media_player.xiao_ai_yin_xiang_5219 is taking over 10 seconds
2023-02-09 19:25:31.934 WARNING (MainThread) [custom_components.xiaomi_miot] None device in xiaomi cloud: 15513084760
2023-02-09 19:26:36.437 ERROR (MainThread) [frontend.js.latest.202302020] :0:0 Script error.
2023-02-09 19:28:42.621 WARNING (MainThread) [homeassistant.components.media_player] Setup of media_player platform xiaomi_miot is taking over 10 seconds.
2023-02-09 19:28:48.780 ERROR (SyncWorker_2) [miio.miioprotocol] Got error when receiving: {'code': -9999, 'message': 'user ack timeout'}
2023-02-09 19:28:48.803 ERROR (MainThread) [custom_components.xiaomi_miot.media_player] Mi AI Speaker(xiaomi.wifispeaker.s12): Got MiioException while fetching the state: Unable to recover failed command, mapping: {'intelligent_speaker.sleep_mode': {'siid': 5, 'piid': 3}, 'intelligent_speaker.audio_id': {'siid': 5, 'piid': 4}, 'microphone.mute': {'siid': 3, 'piid': 1}, 'speaker.volume': {'siid': 2, 'piid': 1}, 'speaker.mute': {'siid': 2, 'piid': 2}}, max_properties: 8/5
2023-02-09 19:29:28.845 WARNING (MainThread) [homeassistant.helpers.entity] Update of media_player.xiaomi_s12_671d_play_control is taking over 10 seconds
2023-02-09 19:29:34.943 ERROR (SyncWorker_4) [miio.miioprotocol] Got error when receiving: {'code': -9999, 'message': 'user ack timeout'}
2023-02-09 19:29:34.948 ERROR (MainThread) [custom_components.xiaomi_miot.media_player] Mi AI Speaker(xiaomi.wifispeaker.s12): Got MiioException while fetching the state: Unable to recover failed command, mapping: {'intelligent_speaker.sleep_mode': {'siid': 5, 'piid': 3}, 'intelligent_speaker.audio_id': {'siid': 5, 'piid': 4}, 'microphone.mute': {'siid': 3, 'piid': 1}, 'speaker.volume': {'siid': 2, 'piid': 1}, 'speaker.mute': {'siid': 2, 'piid': 2}}, max_properties: 8/5
2023-02-09 19:29:58.848 WARNING (MainThread) [homeassistant.helpers.entity] Update of media_player.xiaomi_s12_671d_play_control is taking over 10 seconds
2023-02-09 19:30:04.940 ERROR (SyncWorker_4) [miio.miioprotocol] Got error when receiving: {'code': -9999, 'message': 'user ack timeout'}
2023-02-09 19:30:04.948 ERROR (MainThread) [custom_components.xiaomi_miot.media_player] Mi AI Speaker(xiaomi.wifispeaker.s12): Got MiioException while fetching the state: Unable to recover failed command, mapping: {'intelligent_speaker.sleep_mode': {'siid': 5, 'piid': 3}, 'intelligent_speaker.audio_id': {'siid': 5, 'piid': 4}, 'microphone.mute': {'siid': 3, 'piid': 1}, 'speaker.volume': {'siid': 2, 'piid': 1}, 'speaker.mute': {'siid': 2, 'piid': 2}}, max_properties: 8/5
2023-02-09 19:30:28.850 WARNING (MainThread) [homeassistant.helpers.entity] Update of media_player.xiaomi_s12_671d_play_control is taking over 10 seconds
2023-02-09 19:30:34.963 ERROR (SyncWorker_8) [miio.miioprotocol] Got error when receiving: {'code': -9999, 'message': 'user ack timeout'}
2023-02-09 19:30:34.972 ERROR (MainThread) [custom_components.xiaomi_miot.media_player] Mi AI Speaker(xiaomi.wifispeaker.s12): Got MiioException while fetching the state: Unable to recover failed command, mapping: {'intelligent_speaker.sleep_mode': {'siid': 5, 'piid': 3}, 'intelligent_speaker.audio_id': {'siid': 5, 'piid': 4}, 'microphone.mute': {'siid': 3, 'piid': 1}, 'speaker.volume': {'siid': 2, 'piid': 1}, 'speaker.mute': {'siid': 2, 'piid': 2}}, max_properties: 8/5
2023-02-09 19:30:58.386 ERROR (MainThread) [homeassistant.config_entries] Error occurred loading configuration flow for integration xiaomi_miot_raw: No module named 'custom_components.xiaomi_miot_raw.deps.miio_new'
2023-02-09 19:32:13.626 WARNING (MainThread) [homeassistant.components.sensor] Sensor sensor.xiaomi_band2_410c_vital_signs has device class None, state class None and unit bpm thus indicating it has a numeric value; however, it has the non-numeric value: unknown (<class 'str'>); Please update your configuration if your entity is manually configured, otherwise report it to the custom integration author.
2023-02-09 19:32:43.929 WARNING (MainThread) [custom_components.xiaomi_miot.camera] 摄像机(isa.camera.df3): camera events is empty. {'result': 'ok', 'retriable': False, 'code': 0, 'data': {'thirdPartPlayUnits': [], 'nextTime': 1675337563000, 'isContinue': True}, 'description': '成功', 'ts': 1675942363904}
2023-02-09 19:33:50.427 ERROR (MainThread) [homeassistant.components.automation.edge_ttsce_shi] edge_tts测试: Error executing script. Error for call_service at pos 1: Entity media_player.xiaomi_s12_671d_play_control does not support this service.
2023-02-09 19:33:50.453 ERROR (MainThread) [homeassistant.components.automation.edge_ttsce_shi] Error while executing automation automation.edge_ttsce_shi: Entity media_player.xiaomi_s12_671d_play_control does not support this service.
2023-02-09 19:33:55.642 ERROR (MainThread) [homeassistant.components.automation.edge_ttsce_shi] edge_tts测试: Error executing script. Error for call_service at pos 1: Entity media_player.xiaomi_s12_671d_play_control does not support this service.
2023-02-09 19:33:55.657 ERROR (MainThread) [homeassistant.components.automation.edge_ttsce_shi] Error while executing automation automation.edge_ttsce_shi: Entity media_player.xiaomi_s12_671d_play_control does not support this service.
2023-02-09 19:34:09.927 WARNING (MainThread) [homeassistant.components.automation.edge_tts] 小爱tts: Already running
2023-02-09 19:34:24.526 ERROR (MainThread) [homeassistant.components.automation.edge_ttsce_shi] edge_tts测试: Error executing script. Error for call_service at pos 1: Entity media_player.xiaomi_s12_671d_play_control does not support this service.
2023-02-09 19:34:24.544 ERROR (MainThread) [homeassistant.components.automation.edge_ttsce_shi] Error while executing automation automation.edge_ttsce_shi: Entity media_player.xiaomi_s12_671d_play_control does not support this service.
2023-02-09 19:34:26.613 ERROR (MainThread) [homeassistant.components.automation.edge_ttsce_shi] edge_tts测试: Error executing script. Error for call_service at pos 1: Entity media_player.xiaomi_s12_671d_play_control does not support this service.
2023-02-09 19:34:26.627 ERROR (MainThread) [homeassistant.components.automation.edge_ttsce_shi] Error while executing automation automation.edge_ttsce_shi: Entity media_player.xiaomi_s12_671d_play_control does not support this service.
2023-02-09 19:34:27.428 ERROR (MainThread) [homeassistant.components.automation.edge_ttsce_shi] edge_tts测试: Error executing script. Error for call_service at pos 1: Entity media_player.xiaomi_s12_671d_play_control does not support this service.
2023-02-09 19:34:27.447 ERROR (MainThread) [homeassistant.components.automation.edge_ttsce_shi] Error while executing automation automation.edge_ttsce_shi: Entity media_player.xiaomi_s12_671d_play_control does not support this service.
2023-02-09 19:36:34.556 WARNING (MainThread) [homeassistant.helpers.frame] Detected integration that calls media_source.async_resolve_media without passing an entity_id. Please report issue for media_source using this method at homeassistant/components/media_source/__init__.py, line 147: report("calls media_source.async_resolve_media without passing an entity_id")
2023-02-09 19:37:19.366 ERROR (SyncWorker_4) [custom_components.hello_miai] 还未登录
2023-02-09 19:37:24.981 ERROR (SyncWorker_7) [custom_components.hello_miai] 还未登录
2023-02-09 19:45:12.007 WARNING (MainThread) [homeassistant.components.automation.edge_tts] 小爱tts: Already running
2023-02-09 19:49:18.843 WARNING (MainThread) [homeassistant.components.automation.edge_tts] 小爱tts: Already running
2023-02-09 19:50:03.131 ERROR (SyncWorker_2) [custom_components.hello_miai] 还未登录
2023-02-09 19:50:44.545 WARNING (MainThread) [homeassistant.components.automation.edge_tts] 小爱tts: Already running
2023-02-09 19:50:49.592 WARNING (MainThread) [custom_components.xiaomi_miot.sensor] Mi AI Speaker(xiaomi.wifispeaker.s12): Got exception while fetch xiaoai conversation: ['4d05e31f-9899-4f97-9ecd-10d652f6b523', TypeError('the JSON object must be str, bytes or bytearray, not NoneType')]
2023-02-09 19:54:16.918 ERROR (MainThread) [frontend.js.latest.202302020] :0:0 Script error.
2023-02-09 19:55:14.687 ERROR (MainThread) [frontend.js.latest.202302020] http://192.168.1.2:8123/frontend_latest/346f358e.js:624:2297 TypeError: Attempted to set a non-object key in a WeakMap
2023-02-09 19:55:14.763 ERROR (MainThread) [frontend.js.latest.202302020] http://192.168.1.2:8123/frontend_latest/346f358e.js:624:2297 TypeError: Attempted to set a non-object key in a WeakMap
2023-02-09 19:55:14.771 ERROR (MainThread) [frontend.js.latest.202302020] http://192.168.1.2:8123/frontend_latest/346f358e.js:624:2297 TypeError: Attempted to set a non-object key in a WeakMap
2023-02-09 19:55:14.872 ERROR (MainThread) [frontend.js.latest.202302020] http://192.168.1.2:8123/frontend_latest/346f358e.js:624:2297 TypeError: Attempted to set a non-object key in a WeakMap
2023-02-09 19:55:14.887 ERROR (MainThread) [frontend.js.latest.202302020] http://192.168.1.2:8123/frontend_latest/346f358e.js:624:2297 TypeError: Attempted to set a non-object key in a WeakMap
2023-02-09 19:55:14.974 ERROR (MainThread) [frontend.js.latest.202302020] http://192.168.1.2:8123/frontend_latest/346f358e.js:624:2297 TypeError: Attempted to set a non-object key in a WeakMap
2023-02-09 19:55:14.987 ERROR (MainThread) [frontend.js.latest.202302020] http://192.168.1.2:8123/frontend_latest/346f358e.js:624:2297 TypeError: Attempted to set a non-object key in a WeakMap
2023-02-09 19:55:17.666 ERROR (MainThread) [frontend.js.latest.202302020] http://192.168.1.2:8123/frontend_latest/346f358e.js:624:2297 TypeError: Attempted to set a non-object key in a WeakMap
2023-02-09 19:55:18.698 ERROR (MainThread) [frontend.js.latest.202302020] http://192.168.1.2:8123/frontend_latest/346f358e.js:624:2297 TypeError: Attempted to set a non-object key in a WeakMap
2023-02-09 19:55:19.071 ERROR (MainThread) [frontend.js.latest.202302020] http://192.168.1.2:8123/frontend_latest/346f358e.js:624:2297 TypeError: Attempted to set a non-object key in a WeakMap
2023-02-09 19:55:19.264 ERROR (MainThread) [frontend.js.latest.202302020] http://192.168.1.2:8123/frontend_latest/346f358e.js:624:2297 TypeError: Attempted to set a non-object key in a WeakMap
2023-02-09 19:55:20.037 ERROR (MainThread) [frontend.js.latest.202302020] http://192.168.1.2:8123/frontend_latest/346f358e.js:624:2297 TypeError: Attempted to set a non-object key in a WeakMap
2023-02-09 19:55:20.047 ERROR (MainThread) [frontend.js.latest.202302020] http://192.168.1.2:8123/frontend_latest/346f358e.js:624:2297 TypeError: Attempted to set a non-object key in a WeakMap
2023-02-09 19:55:20.052 ERROR (MainThread) [frontend.js.latest.202302020] http://192.168.1.2:8123/frontend_latest/346f358e.js:624:2297 TypeError: Attempted to set a non-object key in a WeakMap
2023-02-09 19:55:20.068 ERROR (MainThread) [frontend.js.latest.202302020] http://192.168.1.2:8123/frontend_latest/346f358e.js:624:2297 TypeError: Attempted to set a non-object key in a WeakMap
2023-02-09 20:19:43.551 WARNING (MainThread) [homeassistant.helpers.entity] Update of binary_sensor.door_window_sensor_158d0001a64708 is taking over 10 seconds
2023-02-09 20:19:43.562 ERROR (SyncWorker_1) [xiaomi_gateway] Cannot connect to gateway 286c07f0c4e5
2023-02-09 20:19:43.567 ERROR (SyncWorker_1) [xiaomi_gateway] No data in response from hub None
2023-02-09 20:28:13.547 WARNING (MainThread) [homeassistant.helpers.entity] Update of switch.plug_158d00015d1bf5 is taking over 10 seconds
2023-02-09 20:28:13.555 ERROR (SyncWorker_0) [xiaomi_gateway] Cannot connect to gateway 286c07f0c4e5
2023-02-09 20:28:13.561 ERROR (SyncWorker_0) [xiaomi_gateway] No data in response from hub None
2023-02-09 20:28:13.621 WARNING (MainThread) [homeassistant.helpers.entity] Update of binary_sensor.door_window_sensor_158d000128fa46 is taking over 10 seconds
2023-02-09 20:28:13.628 ERROR (SyncWorker_6) [xiaomi_gateway] Cannot connect to gateway 286c07f0c4e5
2023-02-09 20:28:13.632 ERROR (SyncWorker_6) [xiaomi_gateway] No data in response from hub None
2023-02-09 20:46:59.943 WARNING (MainThread) [homeassistant.helpers.service] Unable to find referenced entities switch.er_lou_wo_shi_deng or it is/they are currently not available
2023-02-09 20:51:00.459 WARNING (MainThread) [homeassistant.helpers.service] Unable to find referenced entities switch.er_lou_wo_shi_deng or it is/they are currently not available
2023-02-09 20:53:19.229 WARNING (MainThread) [homeassistant.helpers.service] Unable to find referenced entities switch.er_lou_wo_shi_deng or it is/they are currently not available
2023-02-09 20:54:31.792 WARNING (MainThread) [homeassistant.helpers.entity] Update of media_player.xiaomi_s12_671d_play_control is taking over 10 seconds
2023-02-09 20:56:54.297 ERROR (MainThread) [frontend.js.latest.202302020] :0:0 Script error.
2023-02-09 21:04:13.640 WARNING (MainThread) [homeassistant.helpers.entity] Update of switch.plug_158d00015d1bf5 is taking over 10 seconds
2023-02-09 21:04:13.648 ERROR (SyncWorker_1) [xiaomi_gateway] Cannot connect to gateway 286c07f0c4e5
2023-02-09 21:04:13.654 ERROR (SyncWorker_1) [xiaomi_gateway] No data in response from hub None
2023-02-09 21:04:13.659 WARNING (MainThread) [homeassistant.helpers.entity] Update of binary_sensor.door_window_sensor_158d0001a64708 is taking over 10 seconds
2023-02-09 21:04:13.665 ERROR (SyncWorker_8) [xiaomi_gateway] Cannot connect to gateway 286c07f0c4e5
2023-02-09 21:04:13.671 ERROR (SyncWorker_8) [xiaomi_gateway] No data in response from hub None
2023-02-09 21:05:49.057 WARNING (MainThread) [homeassistant.helpers.service] Unable to find referenced entities switch.er_lou_wo_shi_deng or it is/they are currently not available
2023-02-09 21:10:13.657 WARNING (MainThread) [homeassistant.helpers.entity] Update of switch.plug_158d00015d1bf5 is taking over 10 seconds
2023-02-09 21:10:13.665 ERROR (SyncWorker_4) [xiaomi_gateway] Cannot connect to gateway 286c07f0c4e5
2023-02-09 21:10:13.671 ERROR (SyncWorker_4) [xiaomi_gateway] No data in response from hub None
2023-02-09 21:16:31.525 WARNING (MainThread) [homeassistant.helpers.service] Unable to find referenced entities switch.er_lou_wo_shi_deng or it is/they are currently not available
2023-02-09 21:21:43.704 WARNING (MainThread) [homeassistant.helpers.entity] Update of binary_sensor.door_window_sensor_158d0001a64708 is taking over 10 seconds
2023-02-09 21:21:43.713 ERROR (SyncWorker_1) [xiaomi_gateway] Cannot connect to gateway 286c07f0c4e5
2023-02-09 21:21:43.719 ERROR (SyncWorker_1) [xiaomi_gateway] No data in response from hub None
2023-02-09 21:29:01.355 WARNING (MainThread) [homeassistant.helpers.service] Unable to find referenced entities switch.er_lou_wo_shi_deng or it is/they are currently not available
2023-02-09 21:29:13.776 WARNING (MainThread) [homeassistant.helpers.entity] Update of binary_sensor.door_window_sensor_158d000128fa46 is taking over 10 seconds
2023-02-09 21:29:13.784 ERROR (SyncWorker_0) [xiaomi_gateway] Cannot connect to gateway 286c07f0c4e5
2023-02-09 21:29:13.791 ERROR (SyncWorker_0) [xiaomi_gateway] No data in response from hub None
2023-02-09 21:44:43.810 WARNING (MainThread) [homeassistant.helpers.entity] Update of binary_sensor.door_window_sensor_158d000128fa46 is taking over 10 seconds
2023-02-09 21:44:43.821 ERROR (SyncWorker_4) [xiaomi_gateway] Cannot connect to gateway 286c07f0c4e5
2023-02-09 21:44:43.828 ERROR (SyncWorker_4) [xiaomi_gateway] No data in response from hub None
2023-02-09 21:49:13.777 WARNING (MainThread) [homeassistant.helpers.entity] Update of switch.plug_158d00015d1bf5 is taking over 10 seconds
2023-02-09 21:49:13.784 ERROR (SyncWorker_11) [xiaomi_gateway] Cannot connect to gateway 286c07f0c4e5
2023-02-09 21:49:13.790 ERROR (SyncWorker_11) [xiaomi_gateway] No data in response from hub None
2023-02-09 21:49:43.782 WARNING (MainThread) [homeassistant.helpers.entity] Update of switch.plug_158d00015d1bf5 is taking over 10 seconds
2023-02-09 21:49:43.791 ERROR (SyncWorker_6) [xiaomi_gateway] Cannot connect to gateway 286c07f0c4e5
2023-02-09 21:49:43.794 ERROR (SyncWorker_6) [xiaomi_gateway] No data in response from hub None
2023-02-09 21:49:43.804 WARNING (MainThread) [homeassistant.helpers.entity] Update of binary_sensor.door_window_sensor_158d000128fa46 is taking over 10 seconds
2023-02-09 21:49:43.814 ERROR (SyncWorker_8) [xiaomi_gateway] Cannot connect to gateway 286c07f0c4e5
2023-02-09 21:49:43.818 ERROR (SyncWorker_8) [xiaomi_gateway] No data in response from hub None
2023-02-09 21:50:43.783 WARNING (MainThread) [homeassistant.helpers.entity] Update of switch.plug_158d00015d1bf5 is taking over 10 seconds
2023-02-09 21:50:43.794 ERROR (SyncWorker_5) [xiaomi_gateway] Cannot connect to gateway 286c07f0c4e5
2023-02-09 21:50:43.801 ERROR (SyncWorker_5) [xiaomi_gateway] No data in response from hub None
2023-02-09 21:50:43.945 WARNING (MainThread) [homeassistant.helpers.entity] Update of binary_sensor.door_window_sensor_158d000128fa46 is taking over 10 seconds
2023-02-09 21:50:43.954 ERROR (SyncWorker_2) [xiaomi_gateway] Cannot connect to gateway 286c07f0c4e5
2023-02-09 21:50:43.961 ERROR (SyncWorker_2) [xiaomi_gateway] No data in response from hub None
2023-02-09 21:50:46.139 ERROR (MainThread) [aiohttp.server] Error handling request
Traceback (most recent call last):
  File "/usr/local/lib/python3.10/site-packages/aiohttp/web_protocol.py", line 334, in data_received
    messages, upgraded, tail = self._request_parser.feed_data(data)
  File "aiohttp/_http_parser.pyx", line 551, in aiohttp._http_parser.HttpParser.feed_data
aiohttp.http_exceptions.BadStatusLine: 400, message="Bad status line 'Invalid method encountered'"
2023-02-09 21:51:13.783 WARNING (MainThread) [homeassistant.helpers.entity] Update of switch.plug_158d00015d1bf5 is taking over 10 seconds
2023-02-09 21:51:13.789 WARNING (MainThread) [homeassistant.helpers.entity] Update of binary_sensor.door_window_sensor_158d0001a64708 is taking over 10 seconds
2023-02-09 21:51:13.794 ERROR (SyncWorker_4) [xiaomi_gateway] Cannot connect to gateway 286c07f0c4e5
2023-02-09 21:51:13.796 ERROR (SyncWorker_10) [xiaomi_gateway] Cannot connect to gateway 286c07f0c4e5
2023-02-09 21:51:13.805 ERROR (SyncWorker_4) [xiaomi_gateway] No data in response from hub None
2023-02-09 21:51:13.812 ERROR (SyncWorker_10) [xiaomi_gateway] No data in response from hub None
2023-02-09 21:51:43.784 WARNING (MainThread) [homeassistant.helpers.entity] Update of switch.plug_158d00015d1bf5 is taking over 10 seconds
2023-02-09 21:51:43.789 WARNING (MainThread) [homeassistant.helpers.entity] Update of binary_sensor.door_window_sensor_158d0001a64708 is taking over 10 seconds
2023-02-09 21:51:43.794 ERROR (SyncWorker_9) [xiaomi_gateway] Cannot connect to gateway 286c07f0c4e5
2023-02-09 21:51:43.798 ERROR (SyncWorker_6) [xiaomi_gateway] Cannot connect to gateway 286c07f0c4e5
2023-02-09 21:51:43.799 ERROR (SyncWorker_9) [xiaomi_gateway] No data in response from hub None
2023-02-09 21:51:43.803 ERROR (SyncWorker_6) [xiaomi_gateway] No data in response from hub None
2023-02-09 21:55:13.820 WARNING (MainThread) [homeassistant.helpers.entity] Update of binary_sensor.door_window_sensor_158d000128fa46 is taking over 10 seconds
2023-02-09 21:55:13.834 ERROR (SyncWorker_6) [xiaomi_gateway] Cannot connect to gateway 286c07f0c4e5
2023-02-09 21:55:13.851 ERROR (SyncWorker_6) [xiaomi_gateway] No data in response from hub None
2023-02-09 21:55:43.799 WARNING (MainThread) [homeassistant.helpers.entity] Update of switch.plug_158d00015d1bf5 is taking over 10 seconds
2023-02-09 21:55:43.808 WARNING (MainThread) [homeassistant.helpers.entity] Update of binary_sensor.door_window_sensor_158d0001a64708 is taking over 10 seconds
2023-02-09 21:55:43.809 ERROR (SyncWorker_8) [xiaomi_gateway] Cannot connect to gateway 286c07f0c4e5
2023-02-09 21:55:43.810 ERROR (SyncWorker_6) [xiaomi_gateway] Cannot connect to gateway 286c07f0c4e5
2023-02-09 21:55:43.822 ERROR (SyncWorker_8) [xiaomi_gateway] No data in response from hub None
2023-02-09 21:55:43.825 ERROR (SyncWorker_6) [xiaomi_gateway] No data in response from hub None
2023-02-09 21:56:43.802 WARNING (MainThread) [homeassistant.helpers.entity] Update of switch.plug_158d00015d1bf5 is taking over 10 seconds
2023-02-09 21:56:43.811 WARNING (MainThread) [homeassistant.helpers.entity] Update of binary_sensor.door_window_sensor_158d0001a64708 is taking over 10 seconds
2023-02-09 21:56:43.812 ERROR (SyncWorker_8) [xiaomi_gateway] Cannot connect to gateway 286c07f0c4e5
2023-02-09 21:56:43.814 ERROR (SyncWorker_10) [xiaomi_gateway] Cannot connect to gateway 286c07f0c4e5
2023-02-09 21:56:43.822 ERROR (SyncWorker_8) [xiaomi_gateway] No data in response from hub None
2023-02-09 21:56:43.825 ERROR (SyncWorker_10) [xiaomi_gateway] No data in response from hub None
2023-02-09 21:56:53.837 WARNING (MainThread) [homeassistant.helpers.entity] Update of binary_sensor.door_window_sensor_158d000128fa46 is taking over 10 seconds
2023-02-09 21:56:53.851 ERROR (SyncWorker_9) [xiaomi_gateway] Cannot connect to gateway 286c07f0c4e5
2023-02-09 21:56:53.854 ERROR (SyncWorker_9) [xiaomi_gateway] No data in response from hub None
2023-02-09 21:57:43.807 WARNING (MainThread) [homeassistant.helpers.entity] Update of switch.plug_158d00015d1bf5 is taking over 10 seconds
2023-02-09 21:57:43.817 ERROR (SyncWorker_8) [xiaomi_gateway] Cannot connect to gateway 286c07f0c4e5
2023-02-09 21:57:43.823 ERROR (SyncWorker_8) [xiaomi_gateway] No data in response from hub None
2023-02-09 22:00:43.814 WARNING (MainThread) [homeassistant.helpers.entity] Update of switch.plug_158d00015d1bf5 is taking over 10 seconds
2023-02-09 22:00:43.824 ERROR (SyncWorker_5) [xiaomi_gateway] Cannot connect to gateway 286c07f0c4e5
2023-02-09 22:00:43.828 ERROR (SyncWorker_5) [xiaomi_gateway] No data in response from hub None
2023-02-09 22:01:13.820 WARNING (MainThread) [homeassistant.helpers.entity] Update of binary_sensor.door_window_sensor_158d0001a64708 is taking over 10 seconds
2023-02-09 22:01:13.828 ERROR (SyncWorker_0) [xiaomi_gateway] Cannot connect to gateway 286c07f0c4e5
2023-02-09 22:01:13.832 ERROR (SyncWorker_0) [xiaomi_gateway] No data in response from hub None
2023-02-09 22:11:06.806 ERROR (MainThread) [aiohttp.server] Error handling request
Traceback (most recent call last):
  File "/usr/local/lib/python3.10/site-packages/aiohttp/web_protocol.py", line 334, in data_received
    messages, upgraded, tail = self._request_parser.feed_data(data)
  File "aiohttp/_http_parser.pyx", line 551, in aiohttp._http_parser.HttpParser.feed_data
aiohttp.http_exceptions.BadStatusLine: 400, message="Bad status line 'Invalid method encountered'"
2023-02-09 22:14:43.860 WARNING (MainThread) [homeassistant.helpers.entity] Update of switch.plug_158d00015d1bf5 is taking over 10 seconds
2023-02-09 22:14:43.871 ERROR (SyncWorker_0) [xiaomi_gateway] Cannot connect to gateway 286c07f0c4e5
2023-02-09 22:14:43.877 ERROR (SyncWorker_0) [xiaomi_gateway] No data in response from hub None
2023-02-09 22:20:13.880 WARNING (MainThread) [homeassistant.helpers.entity] Update of switch.plug_158d00015d1bf5 is taking over 10 seconds
2023-02-09 22:20:13.890 ERROR (SyncWorker_0) [xiaomi_gateway] Cannot connect to gateway 286c07f0c4e5
2023-02-09 22:20:13.894 ERROR (SyncWorker_0) [xiaomi_gateway] No data in response from hub None
2023-02-09 22:20:14.009 WARNING (MainThread) [homeassistant.helpers.entity] Update of binary_sensor.door_window_sensor_158d000128fa46 is taking over 10 seconds
2023-02-09 22:20:14.017 ERROR (SyncWorker_7) [xiaomi_gateway] Cannot connect to gateway 286c07f0c4e5
2023-02-09 22:20:14.024 ERROR (SyncWorker_7) [xiaomi_gateway] No data in response from hub None
2023-02-09 22:22:13.888 WARNING (MainThread) [homeassistant.helpers.entity] Update of switch.plug_158d00015d1bf5 is taking over 10 seconds
2023-02-09 22:22:13.898 ERROR (SyncWorker_4) [xiaomi_gateway] Cannot connect to gateway 286c07f0c4e5
2023-02-09 22:22:13.904 ERROR (SyncWorker_4) [xiaomi_gateway] No data in response from hub None
2023-02-09 22:25:13.898 WARNING (MainThread) [homeassistant.helpers.entity] Update of switch.plug_158d00015d1bf5 is taking over 10 seconds
2023-02-09 22:25:13.907 ERROR (SyncWorker_3) [xiaomi_gateway] Cannot connect to gateway 286c07f0c4e5
2023-02-09 22:25:13.914 ERROR (SyncWorker_3) [xiaomi_gateway] No data in response from hub None
2023-02-09 22:27:43.906 WARNING (MainThread) [homeassistant.helpers.entity] Update of switch.plug_158d00015d1bf5 is taking over 10 seconds
2023-02-09 22:27:43.915 ERROR (SyncWorker_5) [xiaomi_gateway] Cannot connect to gateway 286c07f0c4e5
2023-02-09 22:27:43.921 ERROR (SyncWorker_5) [xiaomi_gateway] No data in response from hub None
2023-02-09 22:27:43.932 WARNING (MainThread) [homeassistant.helpers.entity] Update of binary_sensor.door_window_sensor_158d000128fa46 is taking over 10 seconds
2023-02-09 22:27:43.941 ERROR (SyncWorker_7) [xiaomi_gateway] Cannot connect to gateway 286c07f0c4e5
2023-02-09 22:27:43.948 ERROR (SyncWorker_7) [xiaomi_gateway] No data in response from hub None
2023-02-09 22:33:13.916 WARNING (MainThread) [homeassistant.helpers.entity] Update of switch.plug_158d00015d1bf5 is taking over 10 seconds
2023-02-09 22:33:13.920 WARNING (MainThread) [homeassistant.helpers.entity] Update of binary_sensor.door_window_sensor_158d0001a64708 is taking over 10 seconds
2023-02-09 22:33:13.927 ERROR (SyncWorker_3) [xiaomi_gateway] Cannot connect to gateway 286c07f0c4e5
2023-02-09 22:33:13.929 ERROR (SyncWorker_7) [xiaomi_gateway] Cannot connect to gateway 286c07f0c4e5
2023-02-09 22:33:13.938 ERROR (SyncWorker_3) [xiaomi_gateway] No data in response from hub None
2023-02-09 22:33:13.944 ERROR (SyncWorker_7) [xiaomi_gateway] No data in response from hub None
2023-02-09 22:33:23.950 WARNING (MainThread) [homeassistant.helpers.entity] Update of binary_sensor.door_window_sensor_158d000128fa46 is taking over 10 seconds
2023-02-09 22:33:23.957 ERROR (SyncWorker_11) [xiaomi_gateway] Cannot connect to gateway 286c07f0c4e5
2023-02-09 22:33:23.960 ERROR (SyncWorker_11) [xiaomi_gateway] No data in response from hub None
2023-02-09 22:34:43.918 WARNING (MainThread) [homeassistant.helpers.entity] Update of switch.plug_158d00015d1bf5 is taking over 10 seconds
2023-02-09 22:34:43.927 WARNING (MainThread) [homeassistant.helpers.entity] Update of binary_sensor.door_window_sensor_158d0001a64708 is taking over 10 seconds
2023-02-09 22:34:43.928 ERROR (SyncWorker_1) [xiaomi_gateway] Cannot connect to gateway 286c07f0c4e5
2023-02-09 22:34:43.932 ERROR (SyncWorker_3) [xiaomi_gateway] Cannot connect to gateway 286c07f0c4e5
2023-02-09 22:34:43.938 ERROR (SyncWorker_1) [xiaomi_gateway] No data in response from hub None
2023-02-09 22:34:43.943 ERROR (SyncWorker_3) [xiaomi_gateway] No data in response from hub None
2023-02-09 22:35:43.920 WARNING (MainThread) [homeassistant.helpers.entity] Update of switch.plug_158d00015d1bf5 is taking over 10 seconds
2023-02-09 22:35:43.928 ERROR (SyncWorker_9) [xiaomi_gateway] Cannot connect to gateway 286c07f0c4e5
2023-02-09 22:35:43.932 ERROR (SyncWorker_9) [xiaomi_gateway] No data in response from hub None
2023-02-09 22:36:43.926 WARNING (MainThread) [homeassistant.helpers.entity] Update of binary_sensor.door_window_sensor_158d0001a64708 is taking over 10 seconds
2023-02-09 22:36:43.934 ERROR (SyncWorker_10) [xiaomi_gateway] Cannot connect to gateway 286c07f0c4e5
2023-02-09 22:36:43.940 ERROR (SyncWorker_10) [xiaomi_gateway] No data in response from hub None
2023-02-09 22:39:13.928 WARNING (MainThread) [homeassistant.helpers.entity] Update of switch.plug_158d00015d1bf5 is taking over 10 seconds
2023-02-09 22:39:13.936 WARNING (MainThread) [homeassistant.helpers.entity] Update of binary_sensor.door_window_sensor_158d0001a64708 is taking over 10 seconds
2023-02-09 22:39:13.941 ERROR (SyncWorker_7) [xiaomi_gateway] Cannot connect to gateway 286c07f0c4e5
2023-02-09 22:39:13.944 ERROR (SyncWorker_6) [xiaomi_gateway] Cannot connect to gateway 286c07f0c4e5
2023-02-09 22:39:13.952 ERROR (SyncWorker_7) [xiaomi_gateway] No data in response from hub None
2023-02-09 22:39:13.955 ERROR (SyncWorker_6) [xiaomi_gateway] No data in response from hub None
2023-02-09 22:39:43.931 WARNING (MainThread) [homeassistant.helpers.entity] Update of switch.plug_158d00015d1bf5 is taking over 10 seconds
2023-02-09 22:39:43.941 ERROR (SyncWorker_5) [xiaomi_gateway] Cannot connect to gateway 286c07f0c4e5
2023-02-09 22:39:43.945 ERROR (SyncWorker_5) [xiaomi_gateway] No data in response from hub None
2023-02-09 22:42:43.940 WARNING (MainThread) [homeassistant.helpers.entity] Update of switch.plug_158d00015d1bf5 is taking over 10 seconds
2023-02-09 22:42:43.950 WARNING (MainThread) [homeassistant.helpers.entity] Update of binary_sensor.door_window_sensor_158d0001a64708 is taking over 10 seconds
2023-02-09 22:42:43.952 ERROR (SyncWorker_1) [xiaomi_gateway] Cannot connect to gateway 286c07f0c4e5
2023-02-09 22:42:43.953 ERROR (SyncWorker_6) [xiaomi_gateway] Cannot connect to gateway 286c07f0c4e5
2023-02-09 22:42:43.960 ERROR (SyncWorker_1) [xiaomi_gateway] No data in response from hub None
2023-02-09 22:42:43.965 ERROR (SyncWorker_6) [xiaomi_gateway] No data in response from hub None
2023-02-09 22:47:43.978 WARNING (MainThread) [homeassistant.helpers.entity] Update of binary_sensor.door_window_sensor_158d000128fa46 is taking over 10 seconds
2023-02-09 22:47:43.984 ERROR (SyncWorker_7) [xiaomi_gateway] Cannot connect to gateway 286c07f0c4e5
2023-02-09 22:47:43.987 ERROR (SyncWorker_7) [xiaomi_gateway] No data in response from hub None
2023-02-09 22:59:51.100 ERROR (MainThread) [homeassistant.components.broadlink.updater] Error fetching s1 (MP1-1K4S at 192.168.1.33) data: [Errno -4000] Network timeout: No response received within 5s
2023-02-09 23:09:14.046 WARNING (MainThread) [homeassistant.helpers.entity] Update of binary_sensor.door_window_sensor_158d000128fa46 is taking over 10 seconds
2023-02-09 23:09:14.054 ERROR (SyncWorker_10) [xiaomi_gateway] Cannot connect to gateway 286c07f0c4e5
2023-02-09 23:09:14.057 ERROR (SyncWorker_10) [xiaomi_gateway] No data in response from hub None
2023-02-09 23:12:44.036 WARNING (MainThread) [homeassistant.helpers.entity] Update of switch.plug_158d00015d1bf5 is taking over 10 seconds
2023-02-09 23:12:44.041 WARNING (MainThread) [homeassistant.helpers.entity] Update of binary_sensor.door_window_sensor_158d0001a64708 is taking over 10 seconds
2023-02-09 23:12:44.047 ERROR (SyncWorker_8) [xiaomi_gateway] Cannot connect to gateway 286c07f0c4e5
2023-02-09 23:12:44.049 ERROR (SyncWorker_4) [xiaomi_gateway] Cannot connect to gateway 286c07f0c4e5
2023-02-09 23:12:44.058 ERROR (SyncWorker_8) [xiaomi_gateway] No data in response from hub None
2023-02-09 23:12:44.063 ERROR (SyncWorker_4) [xiaomi_gateway] No data in response from hub None
2023-02-09 23:13:44.044 WARNING (MainThread) [homeassistant.helpers.entity] Update of binary_sensor.door_window_sensor_158d0001a64708 is taking over 10 seconds
2023-02-09 23:13:44.054 ERROR (SyncWorker_8) [xiaomi_gateway] Cannot connect to gateway 286c07f0c4e5
2023-02-09 23:13:44.060 ERROR (SyncWorker_8) [xiaomi_gateway] No data in response from hub None
2023-02-09 23:13:54.071 WARNING (MainThread) [homeassistant.helpers.entity] Update of binary_sensor.door_window_sensor_158d000128fa46 is taking over 10 seconds
2023-02-09 23:13:54.081 ERROR (SyncWorker_11) [xiaomi_gateway] Cannot connect to gateway 286c07f0c4e5
2023-02-09 23:13:54.086 ERROR (SyncWorker_11) [xiaomi_gateway] No data in response from hub None
2023-02-09 23:29:56.102 ERROR (MainThread) [homeassistant.components.broadlink.updater] Error fetching s1 (MP1-1K4S at 192.168.1.33) data: [Errno -4000] Network timeout: No response received within 5s
2023-02-10 00:00:00.487 ERROR (MainThread) [homeassistant.components.automation.er_lou_bing_ju_mei_ge_liu_xiao_shi_zhi_xing_kai_guan] 二楼冰柜每隔六小时执行开关: Error executing script. Invalid data for call_service at pos 1: must contain at least one of entity_id, device_id, area_id.
2023-02-10 00:00:00.508 ERROR (MainThread) [homeassistant.components.automation.er_lou_bing_ju_mei_ge_liu_xiao_shi_zhi_xing_kai_guan] Error while executing automation automation.er_lou_bing_ju_mei_ge_liu_xiao_shi_zhi_xing_kai_guan: must contain at least one of entity_id, device_id, area_id.
2023-02-10 01:04:44.446 WARNING (MainThread) [homeassistant.helpers.entity] Update of binary_sensor.door_window_sensor_158d000128fa46 is taking over 10 seconds
2023-02-10 01:04:44.454 ERROR (SyncWorker_10) [xiaomi_gateway] Cannot connect to gateway 286c07f0c4e5
2023-02-10 01:04:44.457 ERROR (SyncWorker_10) [xiaomi_gateway] No data in response from hub None
2023-02-10 01:25:44.365 ERROR (MainThread) [homeassistant.components.broadlink.updater] Error fetching s3 (MP1-1K4S at 192.168.1.35) data: [Errno -4000] Network timeout: No response received within 5s
2023-02-10 01:54:01.101 ERROR (MainThread) [homeassistant.components.broadlink.updater] Error fetching s1 (MP1-1K4S at 192.168.1.33) data: [Errno -4000] Network timeout: No response received within 5s
2023-02-10 01:58:14.606 WARNING (MainThread) [homeassistant.helpers.entity] Update of binary_sensor.door_window_sensor_158d000128fa46 is taking over 10 seconds
2023-02-10 01:58:14.613 ERROR (SyncWorker_8) [xiaomi_gateway] Cannot connect to gateway 286c07f0c4e5
2023-02-10 01:58:14.619 ERROR (SyncWorker_8) [xiaomi_gateway] No data in response from hub None
2023-02-10 02:04:14.607 WARNING (MainThread) [homeassistant.helpers.entity] Update of switch.plug_158d00015d1bf5 is taking over 10 seconds
2023-02-10 02:04:14.611 WARNING (MainThread) [homeassistant.helpers.entity] Update of binary_sensor.door_window_sensor_158d0001a64708 is taking over 10 seconds
2023-02-10 02:04:14.613 ERROR (SyncWorker_6) [xiaomi_gateway] Cannot connect to gateway 286c07f0c4e5
2023-02-10 02:04:14.614 ERROR (SyncWorker_5) [xiaomi_gateway] Cannot connect to gateway 286c07f0c4e5
2023-02-10 02:04:14.624 ERROR (SyncWorker_6) [xiaomi_gateway] No data in response from hub None
2023-02-10 02:04:14.631 ERROR (SyncWorker_5) [xiaomi_gateway] No data in response from hub None
2023-02-10 04:53:45.106 WARNING (MainThread) [homeassistant.helpers.entity] Update of switch.plug_158d00015d1bf5 is taking over 10 seconds
2023-02-10 04:53:45.110 WARNING (MainThread) [homeassistant.helpers.entity] Update of binary_sensor.door_window_sensor_158d0001a64708 is taking over 10 seconds
2023-02-10 04:53:45.119 ERROR (SyncWorker_11) [xiaomi_gateway] Cannot connect to gateway 286c07f0c4e5
2023-02-10 04:53:45.120 ERROR (SyncWorker_8) [xiaomi_gateway] Cannot connect to gateway 286c07f0c4e5
2023-02-10 04:53:45.129 ERROR (SyncWorker_11) [xiaomi_gateway] No data in response from hub None
2023-02-10 04:53:45.135 ERROR (SyncWorker_8) [xiaomi_gateway] No data in response from hub None
2023-02-10 05:09:06.102 ERROR (MainThread) [homeassistant.components.broadlink.updater] Error fetching s1 (MP1-1K4S at 192.168.1.33) data: [Errno -4000] Network timeout: No response received within 5s
2023-02-10 05:17:18.562 ERROR (MainThread) [aiohttp.server] Error handling request
Traceback (most recent call last):
  File "/usr/local/lib/python3.10/site-packages/aiohttp/web_protocol.py", line 334, in data_received
    messages, upgraded, tail = self._request_parser.feed_data(data)
  File "aiohttp/_http_parser.pyx", line 551, in aiohttp._http_parser.HttpParser.feed_data
aiohttp.http_exceptions.BadStatusLine: 400, message="Bad status line 'Invalid method encountered'"
2023-02-10 06:00:00.482 ERROR (MainThread) [homeassistant.components.automation.er_lou_bing_ju_mei_ge_liu_xiao_shi_zhi_xing_kai_guan] 二楼冰柜每隔六小时执行开关: Error executing script. Invalid data for call_service at pos 1: must contain at least one of entity_id, device_id, area_id.
2023-02-10 06:00:00.490 ERROR (MainThread) [homeassistant.components.automation.er_lou_bing_ju_mei_ge_liu_xiao_shi_zhi_xing_kai_guan] Error while executing automation automation.er_lou_bing_ju_mei_ge_liu_xiao_shi_zhi_xing_kai_guan: must contain at least one of entity_id, device_id, area_id.
2023-02-10 06:33:42.500 ERROR (MainThread) [aiohttp.server] Error handling request
Traceback (most recent call last):
  File "/usr/local/lib/python3.10/site-packages/aiohttp/web_protocol.py", line 334, in data_received
    messages, upgraded, tail = self._request_parser.feed_data(data)
  File "aiohttp/_http_parser.pyx", line 551, in aiohttp._http_parser.HttpParser.feed_data
aiohttp.http_exceptions.BadStatusLine: 400, message="Bad status line 'Invalid method encountered'"
2023-02-10 07:12:34.331 ERROR (MainThread) [homeassistant.components.broadlink.updater] Error fetching s2 (MP1-1K4S at 192.168.1.34) data: [Errno -4000] Network timeout: No response received within 5s
2023-02-10 08:00:33.938 ERROR (MainThread) [custom_components.heweather_forecast.weather] Error while accessing: https://devapi.qweather.com/v7/weather/now?location=101100106&key=a4de9580a88d4411bef9344b37273e2a
2023-02-10 08:21:31.372 WARNING (SyncWorker_11) [custom_components.xiaomi_miot.core.xiaomi_cloud] Unauthorized while executing request to https://userprofile.mina.mi.com/device_profile/v2/conversation, logged out.
2023-02-10 08:21:31.386 WARNING (SyncWorker_11) [custom_components.xiaomi_miot.core.xiaomi_cloud] Request xiaomi api: https://userprofile.mina.mi.com/device_profile/v2/conversation {'hardware': 'S12', 'timestamp': 1675988491202, 'limit': 3} failed, response: <!doctype html><html lang="en"><head><title>HTTP Status 401 – Unauthorized</title><style type="text/css">body {font-family:Tahoma,Arial,sans-serif;} h1, h2, h3, b {color:white;background-color:#525D76;} h1 {font-size:22px;} h2 {font-size:16px;} h3 {font-size:14px;} p {font-size:12px;} a {color:black;} .line {height:1px;background-color:#525D76;border:none;}</style></head><body><h1>HTTP Status 401 – Unauthorized</h1></body></html>
2023-02-10 08:29:56.798 WARNING (MainThread) [homeassistant.helpers.service] Unable to find referenced entities switch.er_lou_wo_shi_deng or it is/they are currently not available
2023-02-10 09:00:00.387 WARNING (MainThread) [homeassistant.helpers.service] Unable to find referenced entities switch.er_lou_wo_shi_deng, switch.yi_lou_wo_shi_deng or it is/they are currently not available
2023-02-10 09:21:20.973 WARNING (MainThread) [homeassistant.components.websocket_api.http.connection] [547756671184] Disconnected: Did not receive auth message within 10 seconds
2023-02-10 09:27:39.329 ERROR (MainThread) [homeassistant.components.broadlink.updater] Error fetching s2 (MP1-1K4S at 192.168.1.34) data: [Errno -4000] Network timeout: No response received within 5s
2023-02-10 09:30:47.525 ERROR (MainThread) [frontend.js.latest.202302020] http://home.miaoyang.info:8123/frontend_latest/346f358e.js:624:2294 Uncaught TypeError: Invalid value used as weak map key
2023-02-10 09:30:52.094 ERROR (MainThread) [frontend.js.latest.202302020] http://home.miaoyang.info:8123/frontend_latest/346f358e.js:624:2294 Uncaught TypeError: Invalid value used as weak map key
2023-02-10 09:30:52.794 ERROR (MainThread) [frontend.js.latest.202302020] http://home.miaoyang.info:8123/frontend_latest/346f358e.js:624:2294 Uncaught TypeError: Invalid value used as weak map key
2023-02-10 09:30:53.155 ERROR (MainThread) [frontend.js.latest.202302020] http://home.miaoyang.info:8123/frontend_latest/346f358e.js:624:2294 Uncaught TypeError: Invalid value used as weak map key
2023-02-10 09:30:54.628 ERROR (MainThread) [frontend.js.latest.202302020] http://home.miaoyang.info:8123/frontend_latest/346f358e.js:624:2294 Uncaught TypeError: Invalid value used as weak map key
2023-02-10 09:30:54.741 ERROR (MainThread) [frontend.js.latest.202302020] http://home.miaoyang.info:8123/frontend_latest/346f358e.js:624:2294 Uncaught TypeError: Invalid value used as weak map key
2023-02-10 09:30:55.713 ERROR (MainThread) [frontend.js.latest.202302020] http://home.miaoyang.info:8123/frontend_latest/346f358e.js:624:2294 Uncaught TypeError: Invalid value used as weak map key
2023-02-10 09:30:55.851 ERROR (MainThread) [frontend.js.latest.202302020] http://home.miaoyang.info:8123/frontend_latest/346f358e.js:624:2294 Uncaught TypeError: Invalid value used as weak map key
2023-02-10 09:30:56.067 ERROR (MainThread) [frontend.js.latest.202302020] http://home.miaoyang.info:8123/frontend_latest/346f358e.js:624:2294 Uncaught TypeError: Invalid value used as weak map key
2023-02-10 09:30:56.253 ERROR (MainThread) [frontend.js.latest.202302020] http://home.miaoyang.info:8123/frontend_latest/346f358e.js:624:2294 Uncaught TypeError: Invalid value used as weak map key
2023-02-10 09:30:56.370 ERROR (MainThread) [frontend.js.latest.202302020] http://home.miaoyang.info:8123/frontend_latest/346f358e.js:624:2294 Uncaught TypeError: Invalid value used as weak map key
2023-02-10 09:30:57.216 ERROR (MainThread) [frontend.js.latest.202302020] http://home.miaoyang.info:8123/frontend_latest/346f358e.js:624:2294 Uncaught TypeError: Invalid value used as weak map key
2023-02-10 09:38:20.380 ERROR (MainThread) [homeassistant] Error doing job: Future exception was never retrieved
Traceback (most recent call last):
  File "/usr/local/lib/python3.10/concurrent/futures/thread.py", line 58, in run
    result = self.fn(*self.args, **self.kwargs)
  File "/config/custom_components/hello_miai/__init__.py", line 453, in _stop_listener
    Event.set()
TypeError: Event.set() missing 1 required positional argument: 'self'
